Workbook

Sheet 1233 P- 24 hpi
A1: Time | B1: Storage modulus | C1: Loss modulus | D1: Percent storage modulus | E1: Percent loss modulus | G1: Storage modulus | H1: Loss modulus | I1: Percent storage modulus | J1: Percent loss modulus | L1: Storage modulus | M1: Loss modulus | N1: Percent storage modulus | O1: Percent loss modulus | Q1: Average storage modulus | R1: Average loss modulus | T1: Average storage modulus/initial | U1: Average loss modulus/initial | W1: SD G' | X1: SD G''
A2: s | B2: MPa | C2: MPa | D2: MPa | E2: MPa | G2: MPa | H2: MPa | I2: MPa | J2: MPa | L2: MPa | M2: MPa | N2: MPa | O2: MPa | Q2: MPa | R2: MPa | T2: MPa | U2: MPa | W2: MPa | X2: MPa
A3: 6.26964 | B3: 0.0011883 | C3: 0.000205671 | D3: =B3/$B$3*100 -> 100 | E3: =C3/$C$3*100 -> 100 | G3: 0.000902788 | H3: 0.000172258 | I3: =G3/$G$3*100 -> 100 | J3: =H3/$H$3*100 -> 100 | L3: 0.000722718 | M3: 0.000148069 | N3: =L3/$L$3*100 -> 100 | O3: =M3/$M$3*100 -> 100 | Q3: =AVERAGE(B3,G3,L3) -> 0.00093793533 | R3: =AVERAGE(C3,H3,M3) -> 0.00017533267 | T3: =AVERAGE(D3,I3,N3) -> 100 | U3: =AVERAGE(E3,J3,O3) -> 100 | W3: =_xlfn.STDEV.P(D3,I3,N3) -> 0 | X3: =_xlfn.STDEV.P(E3,J3,O3) -> 0
A4: 12.3698 | B4: 0.00118641 | C4: 0.000205915 | D4: =B4/$B$3*100 -> 99.840949 | E4: =C4/$C$3*100 -> 100.11864 | G4: 0.000901328 | H4: 0.000171364 | I4: =G4/$G$3*100 -> 99.838279 | J4: =H4/$H$3*100 -> 99.481011 | L4: 0.000725984 | M4: 0.000147656 | N4: =L4/$L$3*100 -> 100.45191 | O4: =M4/$M$3*100 -> 99.721076 | Q4: =AVERAGE(B4,G4,L4) -> 0.00093790733 | R4: =AVERAGE(C4,H4,M4) -> 0.00017497833 | T4: =AVERAGE(D4,I4,N4) -> 100.04371 | U4: =AVERAGE(E4,J4,O4) -> 99.773574 | W4: =_xlfn.STDEV.P(D4,I4,N4) -> 0.28863888 | X4: =_xlfn.STDEV.P(E4,J4,O4) -> 0.26294294
A5: 18.654 | B5: 0.00118593 | C5: 0.000204659 | D5: =B5/$B$3*100 -> 99.800555 | E5: =C5/$C$3*100 -> 99.507952 | G5: 0.000902587 | H5: 0.000170426 | I5: =G5/$G$3*100 -> 99.977736 | J5: =H5/$H$3*100 -> 98.936479 | L5: 0.000727934 | M5: 0.000147236 | N5: =L5/$L$3*100 -> 100.72172 | O5: =M5/$M$3*100 -> 99.437424 | Q5: =AVERAGE(B5,G5,L5) -> 0.000938817 | R5: =AVERAGE(C5,H5,M5) -> 0.000174107 | T5: =AVERAGE(D5,I5,N5) -> 100.16667 | U5: =AVERAGE(E5,J5,O5) -> 99.293952 | W5: =_xlfn.STDEV.P(D5,I5,N5) -> 0.39908918 | X5: =_xlfn.STDEV.P(E5,J5,O5) -> 0.25440604
A6: 24.7796 | B6: 0.00118735 | C6: 0.000204961 | D6: =B6/$B$3*100 -> 99.920054 | E6: =C6/$C$3*100 -> 99.654788 | G6: 0.000902875 | H6: 0.000168959 | I6: =G6/$G$3*100 -> 100.00964 | J6: =H6/$H$3*100 -> 98.084849 | L6: 0.000730276 | M6: 0.000146244 | N6: =L6/$L$3*100 -> 101.04577 | O6: =M6/$M$3*100 -> 98.767467 | Q6: =AVERAGE(B6,G6,L6) -> 0.000940167 | R6: =AVERAGE(C6,H6,M6) -> 0.000173388 | T6: =AVERAGE(D6,I6,N6) -> 100.32516 | U6: =AVERAGE(E6,J6,O6) -> 98.835701 | W6: =_xlfn.STDEV.P(D6,I6,N6) -> 0.51086561 | X6: =_xlfn.STDEV.P(E6,J6,O6) -> 0.64273848
A7: 31.0945 | B7: 0.00118597 | C7: 0.000202203 | D7: =B7/$B$3*100 -> 99.803922 | E7: =C7/$C$3*100 -> 98.313812 | G7: 0.000900385 | H7: 0.000168608 | I7: =G7/$G$3*100 -> 99.733825 | J7: =H7/$H$3*100 -> 97.881085 | L7: 0.00073195 | M7: 0.000146171 | N7: =L7/$L$3*100 -> 101.2774 | O7: =M7/$M$3*100 -> 98.718165 | Q7: =AVERAGE(B7,G7,L7) -> 0.000939435 | R7: =AVERAGE(C7,H7,M7) -> 0.00017232733 | T7: =AVERAGE(D7,I7,N7) -> 100.27172 | U7: =AVERAGE(E7,J7,O7) -> 98.304354 | W7: =_xlfn.STDEV.P(D7,I7,N7) -> 0.711702 | X7: =_xlfn.STDEV.P(E7,J7,O7) -> 0.34180184
A8: 37.1619 | B8: 0.00118488 | C8: 0.000202532 | D8: =B8/$B$3*100 -> 99.712194 | E8: =C8/$C$3*100 -> 98.473776 | G8: 0.000899392 | H8: 0.000167951 | I8: =G8/$G$3*100 -> 99.623832 | J8: =H8/$H$3*100 -> 97.499681 | L8: 0.000733013 | M8: 0.000145632 | N8: =L8/$L$3*100 -> 101.42448 | O8: =M8/$M$3*100 -> 98.354146 | Q8: =AVERAGE(B8,G8,L8) -> 0.000939095 | R8: =AVERAGE(C8,H8,M8) -> 0.00017203833 | T8: =AVERAGE(D8,I8,N8) -> 100.2535 | U8: =AVERAGE(E8,J8,O8) -> 98.109201 | W8: =_xlfn.STDEV.P(D8,I8,N8) -> 0.82879369 | X8: =_xlfn.STDEV.P(E8,J8,O8) -> 0.43375411
A9: 43.4417 | B9: 0.00118379 | C9: 0.000201591 | D9: =B9/$B$3*100 -> 99.620466 | E9: =C9/$C$3*100 -> 98.016249 | G9: 0.000899191 | H9: 0.000166873 | I9: =G9/$G$3*100 -> 99.601568 | J9: =H9/$H$3*100 -> 96.873875 | L9: 0.000735504 | M9: 0.000145201 | N9: =L9/$L$3*100 -> 101.76915 | O9: =M9/$M$3*100 -> 98.063065 | Q9: =AVERAGE(B9,G9,L9) -> 0.000939495 | R9: =AVERAGE(C9,H9,M9) -> 0.00017122167 | T9: =AVERAGE(D9,I9,N9) -> 100.3304 | U9: =AVERAGE(E9,J9,O9) -> 97.651063 | W9: =_xlfn.STDEV.P(D9,I9,N9) -> 1.0173852 | X9: =_xlfn.STDEV.P(E9,J9,O9) -> 0.54988715
A10: 49.6718 | B10: 0.00118358 | C10: 0.000201171 | D10: =B10/$B$3*100 -> 99.602794 | E10: =C10/$C$3*100 -> 97.81204 | G10: 0.000898613 | H10: 0.000165865 | I10: =G10/$G$3*100 -> 99.537544 | J10: =H10/$H$3*100 -> 96.288706 | L10: 0.00073628 | M10: 0.00014503 | N10: =L10/$L$3*100 -> 101.87653 | O10: =M10/$M$3*100 -> 97.947578 | Q10: =AVERAGE(B10,G10,L10) -> 0.000939491 | R10: =AVERAGE(C10,H10,M10) -> 0.00017068867 | T10: =AVERAGE(D10,I10,N10) -> 100.33895 | U10: =AVERAGE(E10,J10,O10) -> 97.349442 | W10: =_xlfn.STDEV.P(D10,I10,N10) -> 1.0875541 | X10: =_xlfn.STDEV.P(E10,J10,O10) -> 0.75209123
A11: 55.9278 | B11: 0.00118138 | C11: 0.000200956 | D11: =B11/$B$3*100 -> 99.417655 | E11: =C11/$C$3*100 -> 97.707504 | G11: 0.000897084 | H11: 0.000166078 | I11: =G11/$G$3*100 -> 99.368179 | J11: =H11/$H$3*100 -> 96.412358 | L11: 0.000737808 | M11: 0.000144354 | N11: =L11/$L$3*100 -> 102.08795 | O11: =M11/$M$3*100 -> 97.491035 | Q11: =AVERAGE(B11,G11,L11) -> 0.00093875733 | R11: =AVERAGE(C11,H11,M11) -> 0.00017046267 | T11: =AVERAGE(D11,I11,N11) -> 100.29126 | U11: =AVERAGE(E11,J11,O11) -> 97.203632 | W11: =_xlfn.STDEV.P(D11,I11,N11) -> 1.2706117 | X11: =_xlfn.STDEV.P(E11,J11,O11) -> 0.56645129
A12: 62.0311 | B12: 0.00118053 | C12: 0.000199902 | D12: =B12/$B$3*100 -> 99.346125 | E12: =C12/$C$3*100 -> 97.195035 | G12: 0.000895747 | H12: 0.000165371 | I12: =G12/$G$3*100 -> 99.220083 | J12: =H12/$H$3*100 -> 96.001927 | L12: 0.000739554 | M12: 0.000144344 | N12: =L12/$L$3*100 -> 102.32954 | O12: =M12/$M$3*100 -> 97.484281 | Q12: =AVERAGE(B12,G12,L12) -> 0.00093861033 | R12: =AVERAGE(C12,H12,M12) -> 0.00016987233 | T12: =AVERAGE(D12,I12,N12) -> 100.29858 | U12: =AVERAGE(E12,J12,O12) -> 96.893748 | W12: =_xlfn.STDEV.P(D12,I12,N12) -> 1.4370251 | X12: =_xlfn.STDEV.P(E12,J12,O12) -> 0.64157281
A13: 68.2132 | B13: 0.00118097 | C13: 0.000198939 | D13: =B13/$B$3*100 -> 99.383152 | E13: =C13/$C$3*100 -> 96.726811 | G13: 0.000895932 | H13: 0.000164754 | I13: =G13/$G$3*100 -> 99.240575 | J13: =H13/$H$3*100 -> 95.643744 | L13: 0.000740481 | M13: 0.000144264 | N13: =L13/$L$3*100 -> 102.45781 | O13: =M13/$M$3*100 -> 97.430252 | Q13: =AVERAGE(B13,G13,L13) -> 0.00093912767 | R13: =AVERAGE(C13,H13,M13) -> 0.000169319 | T13: =AVERAGE(D13,I13,N13) -> 100.36051 | U13: =AVERAGE(E13,J13,O13) -> 96.600269 | W13: =_xlfn.STDEV.P(D13,I13,N13) -> 1.4841529 | X13: =_xlfn.STDEV.P(E13,J13,O13) -> 0.73480736
A14: 74.4616 | B14: 0.00117992 | C14: 0.000199124 | D14: =B14/$B$3*100 -> 99.294791 | E14: =C14/$C$3*100 -> 96.816761 | G14: 0.00089443 | H14: 0.0001637 | I14: =G14/$G$3*100 -> 99.074201 | J14: =H14/$H$3*100 -> 95.031871 | L14: 0.000741256 | M14: 0.000144 | N14: =L14/$L$3*100 -> 102.56504 | O14: =M14/$M$3*100 -> 97.251957 | Q14: =AVERAGE(B14,G14,L14) -> 0.00093853533 | R14: =AVERAGE(C14,H14,M14) -> 0.00016894133 | T14: =AVERAGE(D14,I14,N14) -> 100.31134 | U14: =AVERAGE(E14,J14,O14) -> 96.366863 | W14: =_xlfn.STDEV.P(D14,I14,N14) -> 1.5961458 | X14: =_xlfn.STDEV.P(E14,J14,O14) -> 0.96055597
... A109: 692.197 | B109: 0.000774376 | C109: 0.000152461 | D109: =B109/$B$3*100 -> 65.166709 | E109: =C109/$C$3*100 -> 74.128584 | G109: 0.000641633 | H109: 0.000140981 | I109: =G109/$G$3*100 -> 71.072389 | J109: =H109/$H$3*100 -> 81.842933 | L109: 0.000576574 | M109: 0.000129634 | N109: =L109/$L$3*100 -> 79.778558 | O109: =M109/$M$3*100 -> 87.549723 | Q109: =AVERAGE(B109,G109,L109) -> 0.00066419433 | R109: =AVERAGE(C109,H109,M109) -> 0.00014102533 | T109: =AVERAGE(D109,I109,N109) -> 72.005885 | U109: =AVERAGE(E109,J109,O109) -> 81.173747 | W109: =_xlfn.STDEV.P(D109,I109,N109) -> 6.0016718 | X109: =_xlfn.STDEV.P(E109,J109,O109) -> 5.4995517

Sheet 1233 P- 24 hpi IPTG
A1: Time | B1: Storage modulus | C1: Loss modulus | D1: Percent storage modulus | E1: Percent loss modulus | G1: Storage modulus | H1: Loss modulus | I1: Percent storage modulus | J1: Percent loss modulus | L1: Storage modulus | M1: Loss modulus | N1: Percent storage modulus | O1: Percent loss modulus | Q1: Average storage modulus | R1: Average loss modulus | T1: Average storage modulus/initial | U1: Average loss modulus/initial | W1: SD G' | X1: SD G''
A2: s | B2: MPa | C2: MPa | D2: MPa | E2: MPa | G2: MPa | H2: MPa | I2: MPa | J2: MPa | L2: MPa | M2: MPa | N2: MPa | O2: MPa | Q2: MPa | R2: MPa | T2: MPa | U2: MPa | W2: MPa | X2: MPa
A3: 6.26964 | B3: 0.0014671 | C3: 0.000250058 | D3: =B3/$B$3*100 -> 100 | E3: =C3/$C$3*100 -> 100 | Q3: =AVERAGE(B3,G3,L3) -> 0.0014671 | R3: =AVERAGE(C3,H3,M3) -> 0.000250058 | T3: =AVERAGE(D3,I3,N3) -> 100 | U3: =AVERAGE(E3,J3,O3) -> 100 | W3: =_xlfn.STDEV.P(D3,I3,N3) -> 0 | X3: =_xlfn.STDEV.P(E3,J3,O3) -> 0
A4: 12.3698 | B4: 0.00149733 | C4: 0.000251907 | D4: =B4/$B$3*100 -> 102.06053 | E4: =C4/$C$3*100 -> 100.73943 | Q4: =AVERAGE(B4,G4,L4) -> 0.00149733 | R4: =AVERAGE(C4,H4,M4) -> 0.000251907 | T4: =AVERAGE(D4,I4,N4) -> 102.06053 | U4: =AVERAGE(E4,J4,O4) -> 100.73943 | W4: =_xlfn.STDEV.P(D4,I4,N4) -> 0 | X4: =_xlfn.STDEV.P(E4,J4,O4) -> 0
A5: 18.654 | B5: 0.00152524 | C5: 0.000256518 | D5: =B5/$B$3*100 -> 103.96292 | E5: =C5/$C$3*100 -> 102.5834 | Q5: =AVERAGE(B5,G5,L5) -> 0.00152524 | R5: =AVERAGE(C5,H5,M5) -> 0.000256518 | T5: =AVERAGE(D5,I5,N5) -> 103.96292 | U5: =AVERAGE(E5,J5,O5) -> 102.5834 | W5: =_xlfn.STDEV.P(D5,I5,N5) -> 0 | X5: =_xlfn.STDEV.P(E5,J5,O5) -> 0
A6: 24.7796 | B6: 0.00156668 | C6: 0.000261095 | D6: =B6/$B$3*100 -> 106.78754 | E6: =C6/$C$3*100 -> 104.41378 | Q6: =AVERAGE(B6,G6,L6) -> 0.00156668 | R6: =AVERAGE(C6,H6,M6) -> 0.000261095 | T6: =AVERAGE(D6,I6,N6) -> 106.78754 | U6: =AVERAGE(E6,J6,O6) -> 104.41378 | W6: =_xlfn.STDEV.P(D6,I6,N6) -> 0 | X6: =_xlfn.STDEV.P(E6,J6,O6) -> 0
A7: 31.0945 | B7: 0.00159977 | C7: 0.000264159 | D7: =B7/$B$3*100 -> 109.04301 | E7: =C7/$C$3*100 -> 105.63909 | Q7: =AVERAGE(B7,G7,L7) -> 0.00159977 | R7: =AVERAGE(C7,H7,M7) -> 0.000264159 | T7: =AVERAGE(D7,I7,N7) -> 109.04301 | U7: =AVERAGE(E7,J7,O7) -> 105.63909 | W7: =_xlfn.STDEV.P(D7,I7,N7) -> 0 | X7: =_xlfn.STDEV.P(E7,J7,O7) -> 0
A8: 37.1619 | B8: 0.00163046 | C8: 0.000265106 | D8: =B8/$B$3*100 -> 111.13489 | E8: =C8/$C$3*100 -> 106.0178 | Q8: =AVERAGE(B8,G8,L8) -> 0.00163046 | R8: =AVERAGE(C8,H8,M8) -> 0.000265106 | T8: =AVERAGE(D8,I8,N8) -> 111.13489 | U8: =AVERAGE(E8,J8,O8) -> 106.0178 | W8: =_xlfn.STDEV.P(D8,I8,N8) -> 0 | X8: =_xlfn.STDEV.P(E8,J8,O8) -> 0
A9: 43.4417 | B9: 0.00166565 | C9: 0.000279409 | D9: =B9/$B$3*100 -> 113.5335 | E9: =C9/$C$3*100 -> 111.73768 | Q9: =AVERAGE(B9,G9,L9) -> 0.00166565 | R9: =AVERAGE(C9,H9,M9) -> 0.000279409 | T9: =AVERAGE(D9,I9,N9) -> 113.5335 | U9: =AVERAGE(E9,J9,O9) -> 111.73768 | W9: =_xlfn.STDEV.P(D9,I9,N9) -> 0 | X9: =_xlfn.STDEV.P(E9,J9,O9) -> 0
A10: 49.6718 | B10: 0.00171363 | C10: 0.000278513 | D10: =B10/$B$3*100 -> 116.8039 | E10: =C10/$C$3*100 -> 111.37936 | Q10: =AVERAGE(B10,G10,L10) -> 0.00171363 | R10: =AVERAGE(C10,H10,M10) -> 0.000278513 | T10: =AVERAGE(D10,I10,N10) -> 116.8039 | U10: =AVERAGE(E10,J10,O10) -> 111.37936 | W10: =_xlfn.STDEV.P(D10,I10,N10) -> 0 | X10: =_xlfn.STDEV.P(E10,J10,O10) -> 0
A11: 55.9278 | B11: 0.00174813 | C11: 0.000281753 | D11: =B11/$B$3*100 -> 119.15548 | E11: =C11/$C$3*100 -> 112.67506 | Q11: =AVERAGE(B11,G11,L11) -> 0.00174813 | R11: =AVERAGE(C11,H11,M11) -> 0.000281753 | T11: =AVERAGE(D11,I11,N11) -> 119.15548 | U11: =AVERAGE(E11,J11,O11) -> 112.67506 | W11: =_xlfn.STDEV.P(D11,I11,N11) -> 0 | X11: =_xlfn.STDEV.P(E11,J11,O11) -> 0
A12: 62.0311 | B12: 0.00177979 | C12: 0.000282267 | D12: =B12/$B$3*100 -> 121.31348 | E12: =C12/$C$3*100 -> 112.88061 | Q12: =AVERAGE(B12,G12,L12) -> 0.00177979 | R12: =AVERAGE(C12,H12,M12) -> 0.000282267 | T12: =AVERAGE(D12,I12,N12) -> 121.31348 | U12: =AVERAGE(E12,J12,O12) -> 112.88061 | W12: =_xlfn.STDEV.P(D12,I12,N12) -> 0 | X12: =_xlfn.STDEV.P(E12,J12,O12) -> 0
A13: 68.2132 | B13: 0.00181312 | C13: 0.000292916 | D13: =B13/$B$3*100 -> 123.5853 | E13: =C13/$C$3*100 -> 117.13922 | Q13: =AVERAGE(B13,G13,L13) -> 0.00181312 | R13: =AVERAGE(C13,H13,M13) -> 0.000292916 | T13: =AVERAGE(D13,I13,N13) -> 123.5853 | U13: =AVERAGE(E13,J13,O13) -> 117.13922 | W13: =_xlfn.STDEV.P(D13,I13,N13) -> 0 | X13: =_xlfn.STDEV.P(E13,J13,O13) -> 0
A14: 74.4616 | B14: 0.00185132 | C14: 0.000294271 | D14: =B14/$B$3*100 -> 126.18908 | E14: =C14/$C$3*100 -> 117.6811 | Q14: =AVERAGE(B14,G14,L14) -> 0.00185132 | R14: =AVERAGE(C14,H14,M14) -> 0.000294271 | T14: =AVERAGE(D14,I14,N14) -> 126.18908 | U14: =AVERAGE(E14,J14,O14) -> 117.6811 | W14: =_xlfn.STDEV.P(D14,I14,N14) -> 0 | X14: =_xlfn.STDEV.P(E14,J14,O14) -> 0
... A109: 692.197 | B109: 0.0014489 | C109: 0.000293119 | D109: =B109/$B$3*100 -> 98.759457 | E109: =C109/$C$3*100 -> 117.2204 | Q109: =AVERAGE(B109,G109,L109) -> 0.0014489 | R109: =AVERAGE(C109,H109,M109) -> 0.000293119 | T109: =AVERAGE(D109,I109,N109) -> 98.759457 | U109: =AVERAGE(E109,J109,O109) -> 117.2204 | W109: =_xlfn.STDEV.P(D109,I109,N109) -> 0 | X109: =_xlfn.STDEV.P(E109,J109,O109) -> 0

Sheet 1233 P+ 24 hpi
A1: Time | B1: Storage modulus | C1: Loss modulus | D1: Percent storage modulus | E1: Percent loss modulus | G1: Storage modulus | H1: Loss modulus | L1: Storage modulus | M1: Loss modulus | Q1: Average storage modulus | R1: Average loss modulus | T1: Average storage modulus/initial | U1: Average loss modulus/initial | W1: SD G' | X1: SD G''
A2: s | B2: MPa | C2: MPa | D2: MPa | E2: MPa | G2: MPa | H2: MPa | L2: MPa | M2: MPa | Q2: MPa | R2: MPa | T2: MPa | U2: MPa | W2: MPa | X2: MPa
A3: 6.26964 | B3: 0.000397515 | C3: 9.68453e-05 | D3: =B3/$B$3*100 -> 100 | E3: =C3/$C$3*100 -> 100 | Q3: =AVERAGE(B3,G3,L3) -> 0.000397515 | R3: =AVERAGE(C3,H3,M3) -> 9.68453e-05 | T3: =AVERAGE(D3,I3,N3) -> 100 | U3: =AVERAGE(E3,J3,O3) -> 100 | W3: =_xlfn.STDEV.P(D3,I3,N3) -> 0 | X3: =_xlfn.STDEV.P(E3,J3,O3) -> 0
A4: 12.3698 | B4: 0.000397702 | C4: 9.63737e-05 | D4: =B4/$B$3*100 -> 100.04704 | E4: =C4/$C$3*100 -> 99.513038 | Q4: =AVERAGE(B4,G4,L4) -> 0.000397702 | R4: =AVERAGE(C4,H4,M4) -> 9.63737e-05 | T4: =AVERAGE(D4,I4,N4) -> 100.04704 | U4: =AVERAGE(E4,J4,O4) -> 99.513038 | W4: =_xlfn.STDEV.P(D4,I4,N4) -> 0 | X4: =_xlfn.STDEV.P(E4,J4,O4) -> 0
A5: 18.654 | B5: 0.000398579 | C5: 9.61183e-05 | D5: =B5/$B$3*100 -> 100.26766 | E5: =C5/$C$3*100 -> 99.249318 | Q5: =AVERAGE(B5,G5,L5) -> 0.000398579 | R5: =AVERAGE(C5,H5,M5) -> 9.61183e-05 | T5: =AVERAGE(D5,I5,N5) -> 100.26766 | U5: =AVERAGE(E5,J5,O5) -> 99.249318 | W5: =_xlfn.STDEV.P(D5,I5,N5) -> 0 | X5: =_xlfn.STDEV.P(E5,J5,O5) -> 0
A6: 24.7796 | B6: 0.000399237 | C6: 9.62806e-05 | D6: =B6/$B$3*100 -> 100.43319 | E6: =C6/$C$3*100 -> 99.416905 | Q6: =AVERAGE(B6,G6,L6) -> 0.000399237 | R6: =AVERAGE(C6,H6,M6) -> 9.62806e-05 | T6: =AVERAGE(D6,I6,N6) -> 100.43319 | U6: =AVERAGE(E6,J6,O6) -> 99.416905 | W6: =_xlfn.STDEV.P(D6,I6,N6) -> 0 | X6: =_xlfn.STDEV.P(E6,J6,O6) -> 0
A7: 31.0945 | B7: 0.00040063 | C7: 9.48954e-05 | D7: =B7/$B$3*100 -> 100.78362 | E7: =C7/$C$3*100 -> 97.986583 | Q7: =AVERAGE(B7,G7,L7) -> 0.00040063 | R7: =AVERAGE(C7,H7,M7) -> 9.48954e-05 | T7: =AVERAGE(D7,I7,N7) -> 100.78362 | U7: =AVERAGE(E7,J7,O7) -> 97.986583 | W7: =_xlfn.STDEV.P(D7,I7,N7) -> 0 | X7: =_xlfn.STDEV.P(E7,J7,O7) -> 0
A8: 37.1619 | B8: 0.000399851 | C8: 9.6006e-05 | D8: =B8/$B$3*100 -> 100.58765 | E8: =C8/$C$3*100 -> 99.13336 | Q8: =AVERAGE(B8,G8,L8) -> 0.000399851 | R8: =AVERAGE(C8,H8,M8) -> 9.6006e-05 | T8: =AVERAGE(D8,I8,N8) -> 100.58765 | U8: =AVERAGE(E8,J8,O8) -> 99.13336 | W8: =_xlfn.STDEV.P(D8,I8,N8) -> 0 | X8: =_xlfn.STDEV.P(E8,J8,O8) -> 0
A9: 43.4417 | B9: 0.000399588 | C9: 9.62325e-05 | D9: =B9/$B$3*100 -> 100.52149 | E9: =C9/$C$3*100 -> 99.367238 | Q9: =AVERAGE(B9,G9,L9) -> 0.000399588 | R9: =AVERAGE(C9,H9,M9) -> 9.62325e-05 | T9: =AVERAGE(D9,I9,N9) -> 100.52149 | U9: =AVERAGE(E9,J9,O9) -> 99.367238 | W9: =_xlfn.STDEV.P(D9,I9,N9) -> 0 | X9: =_xlfn.STDEV.P(E9,J9,O9) -> 0
A10: 49.6718 | B10: 0.000400735 | C10: 9.58117e-05 | D10: =B10/$B$3*100 -> 100.81003 | E10: =C10/$C$3*100 -> 98.932731 | Q10: =AVERAGE(B10,G10,L10) -> 0.000400735 | R10: =AVERAGE(C10,H10,M10) -> 9.58117e-05 | T10: =AVERAGE(D10,I10,N10) -> 100.81003 | U10: =AVERAGE(E10,J10,O10) -> 98.932731 | W10: =_xlfn.STDEV.P(D10,I10,N10) -> 0 | X10: =_xlfn.STDEV.P(E10,J10,O10) -> 0
A11: 55.9278 | B11: 0.00040164 | C11: 9.55531e-05 | D11: =B11/$B$3*100 -> 101.0377 | E11: =C11/$C$3*100 -> 98.665707 | Q11: =AVERAGE(B11,G11,L11) -> 0.00040164 | R11: =AVERAGE(C11,H11,M11) -> 9.55531e-05 | T11: =AVERAGE(D11,I11,N11) -> 101.0377 | U11: =AVERAGE(E11,J11,O11) -> 98.665707 | W11: =_xlfn.STDEV.P(D11,I11,N11) -> 0 | X11: =_xlfn.STDEV.P(E11,J11,O11) -> 0
A12: 62.0311 | B12: 0.000401682 | C12: 9.55746e-05 | D12: =B12/$B$3*100 -> 101.04826 | E12: =C12/$C$3*100 -> 98.687907 | Q12: =AVERAGE(B12,G12,L12) -> 0.000401682 | R12: =AVERAGE(C12,H12,M12) -> 9.55746e-05 | T12: =AVERAGE(D12,I12,N12) -> 101.04826 | U12: =AVERAGE(E12,J12,O12) -> 98.687907 | W12: =_xlfn.STDEV.P(D12,I12,N12) -> 0 | X12: =_xlfn.STDEV.P(E12,J12,O12) -> 0
A13: 68.2132 | B13: 0.000402051 | C13: 9.54425e-05 | D13: =B13/$B$3*100 -> 101.14109 | E13: =C13/$C$3*100 -> 98.551504 | Q13: =AVERAGE(B13,G13,L13) -> 0.000402051 | R13: =AVERAGE(C13,H13,M13) -> 9.54425e-05 | T13: =AVERAGE(D13,I13,N13) -> 101.14109 | U13: =AVERAGE(E13,J13,O13) -> 98.551504 | W13: =_xlfn.STDEV.P(D13,I13,N13) -> 0 | X13: =_xlfn.STDEV.P(E13,J13,O13) -> 0
A14: 74.4616 | B14: 0.000402539 | C14: 9.52754e-05 | D14: =B14/$B$3*100 -> 101.26385 | E14: =C14/$C$3*100 -> 98.378961 | Q14: =AVERAGE(B14,G14,L14) -> 0.000402539 | R14: =AVERAGE(C14,H14,M14) -> 9.52754e-05 | T14: =AVERAGE(D14,I14,N14) -> 101.26385 | U14: =AVERAGE(E14,J14,O14) -> 98.378961 | W14: =_xlfn.STDEV.P(D14,I14,N14) -> 0 | X14: =_xlfn.STDEV.P(E14,J14,O14) -> 0
... A109: 692.197 | B109: 0.000319244 | C109: 8.72736e-05 | D109: =B109/$B$3*100 -> 80.309925 | E109: =C109/$C$3*100 -> 90.116505 | Q109: =AVERAGE(B109,G109,L109) -> 0.000319244 | R109: =AVERAGE(C109,H109,M109) -> 8.72736e-05 | T109: =AVERAGE(D109,I109,N109) -> 80.309925 | U109: =AVERAGE(E109,J109,O109) -> 90.116505 | W109: =_xlfn.STDEV.P(D109,I109,N109) -> 0 | X109: =_xlfn.STDEV.P(E109,J109,O109) -> 0

Sheet 1234 P- 24 hpi
A1: Time | B1: Storage modulus | C1: Loss modulus | D1: Percent storage modulus | E1: Percent loss modulus | G1: Storage modulus | H1: Loss modulus | I1: Percent storage modulus | J1: Percent loss modulus | L1: Storage modulus | M1: Loss modulus | N1: Percent storage modulus | O1: Percent loss modulus | Q1: Average storage modulus | R1: Average loss modulus | T1: Average storage modulus/initial | U1: Average loss modulus/initial | W1: SD G' | X1: SD G''
A2: s | B2: MPa | C2: MPa | D2: MPa | E2: MPa | G2: MPa | H2: MPa | I2: MPa | J2: MPa | L2: MPa | M2: MPa | N2: MPa | O2: MPa | Q2: MPa | R2: MPa | T2: MPa | U2: MPa | W2: MPa | X2: MPa
A3: 6.26964 | B3: 0.00332246 | C3: 0.000278277 | D3: =B3/$B$3*100 -> 100 | E3: =C3/$C$3*100 -> 100 | G3: 0.000612745 | H3: 0.000127253 | I3: =G3/$G$3*100 -> 100 | J3: =H3/$H$3*100 -> 100 | L3: 0.000767355 | M3: 0.000154473 | N3: =L3/$L$3*100 -> 100 | O3: =M3/$M$3*100 -> 100 | Q3: =AVERAGE(B3,G3,L3) -> 0.00156752 | R3: =AVERAGE(C3,H3,M3) -> 0.00018666767 | T3: =AVERAGE(D3,I3,N3) -> 100 | U3: =AVERAGE(E3,J3,O3) -> 100 | W3: =_xlfn.STDEV.P(D3,I3,N3) -> 0 | X3: =_xlfn.STDEV.P(E3,J3,O3) -> 0
A4: 12.3698 | B4: 0.00331463 | C4: 0.000282721 | D4: =B4/$B$3*100 -> 99.764331 | E4: =C4/$C$3*100 -> 101.59697 | G4: 0.000614146 | H4: 0.000126832 | I4: =G4/$G$3*100 -> 100.22864 | J4: =H4/$H$3*100 -> 99.669163 | L4: 0.000769561 | M4: 0.00015384 | N4: =L4/$L$3*100 -> 100.28748 | O4: =M4/$M$3*100 -> 99.59022 | Q4: =AVERAGE(B4,G4,L4) -> 0.0015661123 | R4: =AVERAGE(C4,H4,M4) -> 0.00018779767 | T4: =AVERAGE(D4,I4,N4) -> 100.09349 | U4: =AVERAGE(E4,J4,O4) -> 100.28545 | W4: =_xlfn.STDEV.P(D4,I4,N4) -> 0.23398319 | X4: =_xlfn.STDEV.P(E4,J4,O4) -> 0.92794386
A5: 18.654 | B5: 0.00332628 | C5: 0.000273988 | D5: =B5/$B$3*100 -> 100.11498 | E5: =C5/$C$3*100 -> 98.45873 | G5: 0.00061477 | H5: 0.000125947 | I5: =G5/$G$3*100 -> 100.33048 | J5: =H5/$H$3*100 -> 98.973698 | L5: 0.000771061 | M5: 0.00015316 | N5: =L5/$L$3*100 -> 100.48296 | O5: =M5/$M$3*100 -> 99.150013 | Q5: =AVERAGE(B5,G5,L5) -> 0.0015707037 | R5: =AVERAGE(C5,H5,M5) -> 0.000184365 | T5: =AVERAGE(D5,I5,N5) -> 100.30947 | U5: =AVERAGE(E5,J5,O5) -> 98.860814 | W5: =_xlfn.STDEV.P(D5,I5,N5) -> 0.15096102 | X5: =_xlfn.STDEV.P(E5,J5,O5) -> 0.29328632
A6: 24.7796 | B6: 0.00332152 | C6: 0.000271544 | D6: =B6/$B$3*100 -> 99.971708 | E6: =C6/$C$3*100 -> 97.580468 | G6: 0.000615461 | H6: 0.000125833 | I6: =G6/$G$3*100 -> 100.44325 | J6: =H6/$H$3*100 -> 98.884113 | L6: 0.00077362 | M6: 0.000153103 | N6: =L6/$L$3*100 -> 100.81644 | O6: =M6/$M$3*100 -> 99.113114 | Q6: =AVERAGE(B6,G6,L6) -> 0.0015702003 | R6: =AVERAGE(C6,H6,M6) -> 0.00018349333 | T6: =AVERAGE(D6,I6,N6) -> 100.41047 | U6: =AVERAGE(E6,J6,O6) -> 98.525898 | W6: =_xlfn.STDEV.P(D6,I6,N6) -> 0.34563918 | X6: =_xlfn.STDEV.P(E6,J6,O6) -> 0.67502522
A7: 31.0945 | B7: 0.00332259 | C7: 0.000269177 | D7: =B7/$B$3*100 -> 100.00391 | E7: =C7/$C$3*100 -> 96.729877 | G7: 0.000615471 | H7: 0.000125571 | I7: =G7/$G$3*100 -> 100.44488 | J7: =H7/$H$3*100 -> 98.678224 | L7: 0.000774895 | M7: 0.000152087 | N7: =L7/$L$3*100 -> 100.9826 | O7: =M7/$M$3*100 -> 98.455393 | Q7: =AVERAGE(B7,G7,L7) -> 0.0015709853 | R7: =AVERAGE(C7,H7,M7) -> 0.00018227833 | T7: =AVERAGE(D7,I7,N7) -> 100.47713 | U7: =AVERAGE(E7,J7,O7) -> 97.954498 | W7: =_xlfn.STDEV.P(D7,I7,N7) -> 0.40019593 | X7: =_xlfn.STDEV.P(E7,J7,O7) -> 0.87070309
A8: 37.1619 | B8: 0.00332421 | C8: 0.000265529 | D8: =B8/$B$3*100 -> 100.05267 | E8: =C8/$C$3*100 -> 95.418953 | G8: 0.000614792 | H8: 0.000125129 | I8: =G8/$G$3*100 -> 100.33407 | J8: =H8/$H$3*100 -> 98.330884 | L8: 0.000776169 | M8: 0.000152353 | N8: =L8/$L$3*100 -> 101.14862 | O8: =M8/$M$3*100 -> 98.627592 | Q8: =AVERAGE(B8,G8,L8) -> 0.0015717237 | R8: =AVERAGE(C8,H8,M8) -> 0.00018100367 | T8: =AVERAGE(D8,I8,N8) -> 100.51179 | U8: =AVERAGE(E8,J8,O8) -> 97.459143 | W8: =_xlfn.STDEV.P(D8,I8,N8) -> 0.46473195 | X8: =_xlfn.STDEV.P(E8,J8,O8) -> 1.4477086
A9: 43.4417 | B9: 0.00332459 | C9: 0.000261774 | D9: =B9/$B$3*100 -> 100.06411 | E9: =C9/$C$3*100 -> 94.069578 | G9: 0.0006156 | H9: 0.000124622 | I9: =G9/$G$3*100 -> 100.46594 | J9: =H9/$H$3*100 -> 97.932465 | L9: 0.000776574 | M9: 0.000152409 | N9: =L9/$L$3*100 -> 101.2014 | O9: =M9/$M$3*100 -> 98.663844 | Q9: =AVERAGE(B9,G9,L9) -> 0.0015722547 | R9: =AVERAGE(C9,H9,M9) -> 0.00017960167 | T9: =AVERAGE(D9,I9,N9) -> 100.57715 | U9: =AVERAGE(E9,J9,O9) -> 96.888629 | W9: =_xlfn.STDEV.P(D9,I9,N9) -> 0.47090942 | X9: =_xlfn.STDEV.P(E9,J9,O9) -> 2.0156083
A10: 49.6718 | B10: 0.00333034 | C10: 0.00026724 | D10: =B10/$B$3*100 -> 100.23717 | E10: =C10/$C$3*100 -> 96.033808 | G10: 0.000615209 | H10: 0.000124766 | I10: =G10/$G$3*100 -> 100.40212 | J10: =H10/$H$3*100 -> 98.045626 | L10: 0.000777221 | M10: 0.000151578 | N10: =L10/$L$3*100 -> 101.28572 | O10: =M10/$M$3*100 -> 98.125886 | Q10: =AVERAGE(B10,G10,L10) -> 0.0015742567 | R10: =AVERAGE(C10,H10,M10) -> 0.00018119467 | T10: =AVERAGE(D10,I10,N10) -> 100.64167 | U10: =AVERAGE(E10,J10,O10) -> 97.401773 | W10: =_xlfn.STDEV.P(D10,I10,N10) -> 0.46035979 | X10: =_xlfn.STDEV.P(E10,J10,O10) -> 0.96785228
A11: 55.9278 | B11: 0.00332554 | C11: 0.0002575 | D11: =B11/$B$3*100 -> 100.0927 | E11: =C11/$C$3*100 -> 92.533698 | G11: 0.000614466 | H11: 0.000124397 | I11: =G11/$G$3*100 -> 100.28087 | J11: =H11/$H$3*100 -> 97.755652 | L11: 0.000778364 | M11: 0.000151482 | N11: =L11/$L$3*100 -> 101.43467 | O11: =M11/$M$3*100 -> 98.063739 | Q11: =AVERAGE(B11,G11,L11) -> 0.00157279 | R11: =AVERAGE(C11,H11,M11) -> 0.000177793 | T11: =AVERAGE(D11,I11,N11) -> 100.60275 | U11: =AVERAGE(E11,J11,O11) -> 96.117697 | W11: =_xlfn.STDEV.P(D11,I11,N11) -> 0.59325244 | X11: =_xlfn.STDEV.P(E11,J11,O11) -> 2.5373886
A12: 62.0311 | B12: 0.00332556 | C12: 0.000256762 | D12: =B12/$B$3*100 -> 100.0933 | E12: =C12/$C$3*100 -> 92.268495 | G12: 0.000614135 | H12: 0.000124075 | I12: =G12/$G$3*100 -> 100.22685 | J12: =H12/$H$3*100 -> 97.502613 | L12: 0.000777739 | M12: 0.000151962 | N12: =L12/$L$3*100 -> 101.35322 | O12: =M12/$M$3*100 -> 98.374473 | Q12: =AVERAGE(B12,G12,L12) -> 0.001572478 | R12: =AVERAGE(C12,H12,M12) -> 0.00017759967 | T12: =AVERAGE(D12,I12,N12) -> 100.55779 | U12: =AVERAGE(E12,J12,O12) -> 96.048527 | W12: =_xlfn.STDEV.P(D12,I12,N12) -> 0.5650894 | X12: =_xlfn.STDEV.P(E12,J12,O12) -> 2.6964812
A13: 68.2132 | B13: 0.00332463 | C13: 0.000254934 | D13: =B13/$B$3*100 -> 100.06531 | E13: =C13/$C$3*100 -> 91.611596 | G13: 0.000614184 | H13: 0.000123672 | I13: =G13/$G$3*100 -> 100.23484 | J13: =H13/$H$3*100 -> 97.185921 | L13: 0.00077837 | M13: 0.000151388 | N13: =L13/$L$3*100 -> 101.43545 | O13: =M13/$M$3*100 -> 98.002887 | Q13: =AVERAGE(B13,G13,L13) -> 0.0015723947 | R13: =AVERAGE(C13,H13,M13) -> 0.00017666467 | T13: =AVERAGE(D13,I13,N13) -> 100.57854 | U13: =AVERAGE(E13,J13,O13) -> 95.600135 | W13: =_xlfn.STDEV.P(D13,I13,N13) -> 0.60986982 | X13: =_xlfn.STDEV.P(E13,J13,O13) -> 2.8399754
A14: 74.4616 | B14: 0.00332248 | C14: 0.000252563 | D14: =B14/$B$3*100 -> 100.0006 | E14: =C14/$C$3*100 -> 90.759567 | G14: 0.000613671 | H14: 0.000123141 | I14: =G14/$G$3*100 -> 100.15112 | J14: =H14/$H$3*100 -> 96.768642 | L14: 0.000778887 | M14: 0.000151108 | N14: =L14/$L$3*100 -> 101.50282 | O14: =M14/$M$3*100 -> 97.821626 | Q14: =AVERAGE(B14,G14,L14) -> 0.0015716793 | R14: =AVERAGE(C14,H14,M14) -> 0.000175604 | T14: =AVERAGE(D14,I14,N14) -> 100.55152 | U14: =AVERAGE(E14,J14,O14) -> 95.116612 | W14: =_xlfn.STDEV.P(D14,I14,N14) -> 0.67547731 | X14: =_xlfn.STDEV.P(E14,J14,O14) -> 3.1107419
... A109: 692.197 | B109: 0.0025727 | C109: 0.000216926 | D109: =B109/$B$3*100 -> 77.433588 | E109: =C109/$C$3*100 -> 77.953262 | G109: 0.000458166 | H109: 0.000106837 | I109: =G109/$G$3*100 -> 74.772703 | J109: =H109/$H$3*100 -> 83.95637 | L109: 0.000645909 | M109: 0.000146803 | N109: =L109/$L$3*100 -> 84.173427 | O109: =M109/$M$3*100 -> 95.034731 | Q109: =AVERAGE(B109,G109,L109) -> 0.0012255917 | R109: =AVERAGE(C109,H109,M109) -> 0.00015685533 | T109: =AVERAGE(D109,I109,N109) -> 78.793239 | U109: =AVERAGE(E109,J109,O109) -> 85.648121 | W109: =_xlfn.STDEV.P(D109,I109,N109) -> 3.9564201 | X109: =_xlfn.STDEV.P(E109,J109,O109) -> 7.0753402

Sheet 1234 P+ 24 hpi
A1: Time | B1: Storage modulus | C1: Loss modulus | D1: Percent storage modulus | E1: Percent loss modulus | G1: Storage modulus | H1: Loss modulus | L1: Storage modulus | M1: Loss modulus | Q1: Average storage modulus | R1: Average loss modulus | T1: Average storage modulus/initial | U1: Average loss modulus/initial | W1: SD G' | X1: SD G''
A2: s | B2: MPa | C2: MPa | D2: MPa | E2: MPa | G2: MPa | H2: MPa | L2: MPa | M2: MPa | Q2: MPa | R2: MPa | T2: MPa | U2: MPa | W2: MPa | X2: MPa
A3: 6.26964 | B3: 0.00917003 | C3: 0.00112453 | D3: =B3/$B$3*100 -> 100 | E3: =C3/$C$3*100 -> 100 | Q3: =AVERAGE(B3,G3,L3) -> 0.00917003 | R3: =AVERAGE(C3,H3,M3) -> 0.00112453 | T3: =AVERAGE(D3,I3,N3) -> 100 | U3: =AVERAGE(E3,J3,O3) -> 100 | W3: =_xlfn.STDEV.P(D3,I3,N3) -> 0 | X3: =_xlfn.STDEV.P(E3,J3,O3) -> 0
A4: 12.3698 | B4: 0.00920799 | C4: 0.00109516 | D4: =B4/$B$3*100 -> 100.41396 | E4: =C4/$C$3*100 -> 97.388242 | Q4: =AVERAGE(B4,G4,L4) -> 0.00920799 | R4: =AVERAGE(C4,H4,M4) -> 0.00109516 | T4: =AVERAGE(D4,I4,N4) -> 100.41396 | U4: =AVERAGE(E4,J4,O4) -> 97.388242 | W4: =_xlfn.STDEV.P(D4,I4,N4) -> 0 | X4: =_xlfn.STDEV.P(E4,J4,O4) -> 0
A5: 18.654 | B5: 0.00923512 | C5: 0.00107884 | D5: =B5/$B$3*100 -> 100.70981 | E5: =C5/$C$3*100 -> 95.936969 | Q5: =AVERAGE(B5,G5,L5) -> 0.00923512 | R5: =AVERAGE(C5,H5,M5) -> 0.00107884 | T5: =AVERAGE(D5,I5,N5) -> 100.70981 | U5: =AVERAGE(E5,J5,O5) -> 95.936969 | W5: =_xlfn.STDEV.P(D5,I5,N5) -> 0 | X5: =_xlfn.STDEV.P(E5,J5,O5) -> 0
A6: 24.7796 | B6: 0.00926129 | C6: 0.00106505 | D6: =B6/$B$3*100 -> 100.9952 | E6: =C6/$C$3*100 -> 94.710679 | Q6: =AVERAGE(B6,G6,L6) -> 0.00926129 | R6: =AVERAGE(C6,H6,M6) -> 0.00106505 | T6: =AVERAGE(D6,I6,N6) -> 100.9952 | U6: =AVERAGE(E6,J6,O6) -> 94.710679 | W6: =_xlfn.STDEV.P(D6,I6,N6) -> 0 | X6: =_xlfn.STDEV.P(E6,J6,O6) -> 0
A7: 31.0945 | B7: 0.00928723 | C7: 0.00105367 | D7: =B7/$B$3*100 -> 101.27808 | E7: =C7/$C$3*100 -> 93.698701 | Q7: =AVERAGE(B7,G7,L7) -> 0.00928723 | R7: =AVERAGE(C7,H7,M7) -> 0.00105367 | T7: =AVERAGE(D7,I7,N7) -> 101.27808 | U7: =AVERAGE(E7,J7,O7) -> 93.698701 | W7: =_xlfn.STDEV.P(D7,I7,N7) -> 0 | X7: =_xlfn.STDEV.P(E7,J7,O7) -> 0
A8: 37.1619 | B8: 0.00930925 | C8: 0.00104448 | D8: =B8/$B$3*100 -> 101.51821 | E8: =C8/$C$3*100 -> 92.88147 | Q8: =AVERAGE(B8,G8,L8) -> 0.00930925 | R8: =AVERAGE(C8,H8,M8) -> 0.00104448 | T8: =AVERAGE(D8,I8,N8) -> 101.51821 | U8: =AVERAGE(E8,J8,O8) -> 92.88147 | W8: =_xlfn.STDEV.P(D8,I8,N8) -> 0 | X8: =_xlfn.STDEV.P(E8,J8,O8) -> 0
A9: 43.4417 | B9: 0.00932535 | C9: 0.00103714 | D9: =B9/$B$3*100 -> 101.69378 | E9: =C9/$C$3*100 -> 92.228753 | Q9: =AVERAGE(B9,G9,L9) -> 0.00932535 | R9: =AVERAGE(C9,H9,M9) -> 0.00103714 | T9: =AVERAGE(D9,I9,N9) -> 101.69378 | U9: =AVERAGE(E9,J9,O9) -> 92.228753 | W9: =_xlfn.STDEV.P(D9,I9,N9) -> 0 | X9: =_xlfn.STDEV.P(E9,J9,O9) -> 0
A10: 49.6718 | B10: 0.0093391 | C10: 0.0010309 | D10: =B10/$B$3*100 -> 101.84372 | E10: =C10/$C$3*100 -> 91.673855 | Q10: =AVERAGE(B10,G10,L10) -> 0.0093391 | R10: =AVERAGE(C10,H10,M10) -> 0.0010309 | T10: =AVERAGE(D10,I10,N10) -> 101.84372 | U10: =AVERAGE(E10,J10,O10) -> 91.673855 | W10: =_xlfn.STDEV.P(D10,I10,N10) -> 0 | X10: =_xlfn.STDEV.P(E10,J10,O10) -> 0
A11: 55.9278 | B11: 0.00935414 | C11: 0.00102028 | D11: =B11/$B$3*100 -> 102.00774 | E11: =C11/$C$3*100 -> 90.72946 | Q11: =AVERAGE(B11,G11,L11) -> 0.00935414 | R11: =AVERAGE(C11,H11,M11) -> 0.00102028 | T11: =AVERAGE(D11,I11,N11) -> 102.00774 | U11: =AVERAGE(E11,J11,O11) -> 90.72946 | W11: =_xlfn.STDEV.P(D11,I11,N11) -> 0 | X11: =_xlfn.STDEV.P(E11,J11,O11) -> 0
A12: 62.0311 | B12: 0.00936714 | C12: 0.00101869 | D12: =B12/$B$3*100 -> 102.1495 | E12: =C12/$C$3*100 -> 90.588068 | Q12: =AVERAGE(B12,G12,L12) -> 0.00936714 | R12: =AVERAGE(C12,H12,M12) -> 0.00101869 | T12: =AVERAGE(D12,I12,N12) -> 102.1495 | U12: =AVERAGE(E12,J12,O12) -> 90.588068 | W12: =_xlfn.STDEV.P(D12,I12,N12) -> 0 | X12: =_xlfn.STDEV.P(E12,J12,O12) -> 0
A13: 68.2132 | B13: 0.00940136 | C13: 0.00101419 | D13: =B13/$B$3*100 -> 102.52267 | E13: =C13/$C$3*100 -> 90.187901 | Q13: =AVERAGE(B13,G13,L13) -> 0.00940136 | R13: =AVERAGE(C13,H13,M13) -> 0.00101419 | T13: =AVERAGE(D13,I13,N13) -> 102.52267 | U13: =AVERAGE(E13,J13,O13) -> 90.187901 | W13: =_xlfn.STDEV.P(D13,I13,N13) -> 0 | X13: =_xlfn.STDEV.P(E13,J13,O13) -> 0
A14: 74.4616 | B14: 0.00939615 | C14: 0.0010085 | D14: =B14/$B$3*100 -> 102.46586 | E14: =C14/$C$3*100 -> 89.681912 | Q14: =AVERAGE(B14,G14,L14) -> 0.00939615 | R14: =AVERAGE(C14,H14,M14) -> 0.0010085 | T14: =AVERAGE(D14,I14,N14) -> 102.46586 | U14: =AVERAGE(E14,J14,O14) -> 89.681912 | W14: =_xlfn.STDEV.P(D14,I14,N14) -> 0 | X14: =_xlfn.STDEV.P(E14,J14,O14) -> 0
... A109: 692.197 | B109: 0.00624759 | C109: 0.000726791 | D109: =B109/$B$3*100 -> 68.13053 | E109: =C109/$C$3*100 -> 64.630646 | Q109: =AVERAGE(B109,G109,L109) -> 0.00624759 | R109: =AVERAGE(C109,H109,M109) -> 0.000726791 | T109: =AVERAGE(D109,I109,N109) -> 68.13053 | U109: =AVERAGE(E109,J109,O109) -> 64.630646 | W109: =_xlfn.STDEV.P(D109,I109,N109) -> 0 | X109: =_xlfn.STDEV.P(E109,J109,O109) -> 0

Sheet 1250 P- 24 hpi
A1: Time | B1: Storage modulus | C1: Loss modulus | D1: Percent storage modulus | E1: Percent loss modulus | G1: Storage modulus | H1: Loss modulus | I1: Percent storage modulus | J1: Percent loss modulus | L1: Storage modulus | M1: Loss modulus | N1: Percent storage modulus | O1: Percent loss modulus | Q1: Storage modulus | R1: Loss modulus | S1: Percent storage modulus | T1: Percent loss modulus | V1: Storage modulus | W1: Loss modulus | X1: Percent storage modulus | Y1: Percent loss modulus | AA1: Average storage modulus | AB1: Average loss modulus | AD1: Average storage modulus/initial | AE1: Average loss modulus/initial | AG1: SD G' | AH1: SD G''
A2: s | B2: MPa | C2: MPa | D2: MPa | E2: MPa | G2: MPa | H2: MPa | I2: MPa | J2: MPa | L2: MPa | M2: MPa | N2: MPa | O2: MPa | Q2: MPa | R2: MPa | S2: MPa | T2: MPa | V2: MPa | W2: MPa | X2: MPa | Y2: MPa | AA2: MPa | AB2: MPa | AD2: MPa | AE2: MPa | AG2: MPa | AH2: MPa
A3: 6.26964 | B3: 0.00174361 | C3: 0.000266529 | D3: =B3/$B$3*100 -> 100 | E3: =C3/$C$3*100 -> 100 | G3: 0.0018047 | H3: 0.000277807 | I3: =G3/$G$3*100 -> 100 | J3: =H3/$H$3*100 -> 100 | L3: 0.00169793 | M3: 0.000234855 | N3: =L3/$L$3*100 -> 100 | O3: =M3/$M$3*100 -> 100 | Q3: 0.00176931 | R3: 0.000273438 | S3: =Q3/$Q$3*100 -> 100 | T3: =R3/$R$3*100 -> 100 | V3: 0.00149043 | W3: 0.000229579 | X3: =V3/$V$3*100 -> 100 | Y3: =W3/$W$3*100 -> 100 | AA3: =AVERAGE(B3,G3,L3,Q3,V3) -> 0.001701196 | AB3: =AVERAGE(C3,H3,M3,R3,W3) -> 0.0002564416 | AD3: =AVERAGE(D3,I3,N3,S3,X3) -> 100 | AE3: =AVERAGE(E3,J3,O3,T3,Y3) -> 100 | AG3: =_xlfn.STDEV.P(D3,I3,N3,S3,X3) -> 0 | AH3: =_xlfn.STDEV.P(E3,J3,O3,T3,Y3) -> 0
A4: 12.3698 | B4: 0.00174599 | C4: 0.000265461 | D4: =B4/$B$3*100 -> 100.1365 | E4: =C4/$C$3*100 -> 99.599293 | G4: 0.00184078 | H4: 0.00028409 | I4: =G4/$G$3*100 -> 101.99922 | J4: =H4/$H$3*100 -> 102.26164 | L4: 0.00174163 | M4: 0.000238581 | N4: =L4/$L$3*100 -> 102.57372 | O4: =M4/$M$3*100 -> 101.58651 | Q4: 0.00180583 | R4: 0.00028088 | S4: =Q4/$Q$3*100 -> 102.06408 | T4: =R4/$R$3*100 -> 102.72164 | V4: 0.00150485 | W4: 0.000230594 | X4: =V4/$V$3*100 -> 100.96751 | Y4: =W4/$W$3*100 -> 100.44211 | AA4: =AVERAGE(B4,G4,L4,Q4,V4) -> 0.001727816 | AB4: =AVERAGE(C4,H4,M4,R4,W4) -> 0.0002599212 | AD4: =AVERAGE(D4,I4,N4,S4,X4) -> 101.54821 | AE4: =AVERAGE(E4,J4,O4,T4,Y4) -> 101.32224 | AG4: =_xlfn.STDEV.P(D4,I4,N4,S4,X4) -> 0.8776513 | AH4: =_xlfn.STDEV.P(E4,J4,O4,T4,Y4) -> 1.1535862
A5: 18.654 | B5: 0.00175022 | C5: 0.000263972 | D5: =B5/$B$3*100 -> 100.3791 | E5: =C5/$C$3*100 -> 99.04063 | G5: 0.00187484 | H5: 0.000289517 | I5: =G5/$G$3*100 -> 103.88652 | J5: =H5/$H$3*100 -> 104.21516 | L5: 0.00178175 | M5: 0.000242288 | N5: =L5/$L$3*100 -> 104.9366 | O5: =M5/$M$3*100 -> 103.16493 | Q5: 0.00184886 | R5: 0.000283823 | S5: =Q5/$Q$3*100 -> 104.4961 | T5: =R5/$R$3*100 -> 103.79794 | V5: 0.00151885 | W5: 0.000230047 | X5: =V5/$V$3*100 -> 101.90683 | Y5: =W5/$W$3*100 -> 100.20385 | AA5: =AVERAGE(B5,G5,L5,Q5,V5) -> 0.001754904 | AB5: =AVERAGE(C5,H5,M5,R5,W5) -> 0.0002619294 | AD5: =AVERAGE(D5,I5,N5,S5,X5) -> 103.12103 | AE5: =AVERAGE(E5,J5,O5,T5,Y5) -> 102.0845 | AG5: =_xlfn.STDEV.P(D5,I5,N5,S5,X5) -> 1.7184618 | AH5: =_xlfn.STDEV.P(E5,J5,O5,T5,Y5) -> 2.0709842
A6: 24.7796 | B6: 0.0017535 | C6: 0.000261691 | D6: =B6/$B$3*100 -> 100.56721 | E6: =C6/$C$3*100 -> 98.184813 | G6: 0.00192738 | H6: 0.000298118 | I6: =G6/$G$3*100 -> 106.79781 | J6: =H6/$H$3*100 -> 107.31119 | L6: 0.0018233 | M6: 0.000243417 | N6: =L6/$L$3*100 -> 107.3837 | O6: =M6/$M$3*100 -> 103.64565 | Q6: 0.0018854 | R6: 0.000289465 | S6: =Q6/$Q$3*100 -> 106.56131 | T6: =R6/$R$3*100 -> 105.86129 | V6: 0.00153061 | W6: 0.000229925 | X6: =V6/$V$3*100 -> 102.69587 | Y6: =W6/$W$3*100 -> 100.15071 | AA6: =AVERAGE(B6,G6,L6,Q6,V6) -> 0.001784038 | AB6: =AVERAGE(C6,H6,M6,R6,W6) -> 0.0002645232 | AD6: =AVERAGE(D6,I6,N6,S6,X6) -> 104.80118 | AE6: =AVERAGE(E6,J6,O6,T6,Y6) -> 103.03073 | AG6: =_xlfn.STDEV.P(D6,I6,N6,S6,X6) -> 2.6874819 | AH6: =_xlfn.STDEV.P(E6,J6,O6,T6,Y6) -> 3.4202334
A7: 31.0945 | B7: 0.00175832 | C7: 0.000261794 | D7: =B7/$B$3*100 -> 100.84365 | E7: =C7/$C$3*100 -> 98.223458 | G7: 0.00198056 | H7: 0.000307058 | I7: =G7/$G$3*100 -> 109.74456 | J7: =H7/$H$3*100 -> 110.52925 | L7: 0.00186494 | M7: 0.000247454 | N7: =L7/$L$3*100 -> 109.83609 | O7: =M7/$M$3*100 -> 105.36459 | Q7: 0.00192301 | R7: 0.000293473 | S7: =Q7/$Q$3*100 -> 108.687 | T7: =R7/$R$3*100 -> 107.32707 | V7: 0.00154893 | W7: 0.000231864 | X7: =V7/$V$3*100 -> 103.92504 | Y7: =W7/$W$3*100 -> 100.9953 | AA7: =AVERAGE(B7,G7,L7,Q7,V7) -> 0.001815152 | AB7: =AVERAGE(C7,H7,M7,R7,W7) -> 0.0002683286 | AD7: =AVERAGE(D7,I7,N7,S7,X7) -> 106.60727 | AE7: =AVERAGE(E7,J7,O7,T7,Y7) -> 104.48793 | AG7: =_xlfn.STDEV.P(D7,I7,N7,S7,X7) -> 3.6057398 | AH7: =_xlfn.STDEV.P(E7,J7,O7,T7,Y7) -> 4.3992933
A8: 37.1619 | B8: 0.00176199 | C8: 0.000261238 | D8: =B8/$B$3*100 -> 101.05413 | E8: =C8/$C$3*100 -> 98.01485 | G8: 0.00201922 | H8: 0.000313553 | I8: =G8/$G$3*100 -> 111.88674 | J8: =H8/$H$3*100 -> 112.86721 | L8: 0.0019033 | M8: 0.000252739 | N8: =L8/$L$3*100 -> 112.09532 | O8: =M8/$M$3*100 -> 107.61491 | Q8: 0.00196406 | R8: 0.000293926 | S8: =Q8/$Q$3*100 -> 111.00712 | T8: =R8/$R$3*100 -> 107.49274 | V8: 0.00156195 | W8: 0.000232613 | X8: =V8/$V$3*100 -> 104.79862 | Y8: =W8/$W$3*100 -> 101.32155 | AA8: =AVERAGE(B8,G8,L8,Q8,V8) -> 0.001842104 | AB8: =AVERAGE(C8,H8,M8,R8,W8) -> 0.0002708138 | AD8: =AVERAGE(D8,I8,N8,S8,X8) -> 108.16838 | AE8: =AVERAGE(E8,J8,O8,T8,Y8) -> 105.46225 | AG8: =_xlfn.STDEV.P(D8,I8,N8,S8,X8) -> 4.4558557 | AH8: =_xlfn.STDEV.P(E8,J8,O8,T8,Y8) -> 5.2191836
A9: 43.4417 | B9: 0.00176047 | C9: 0.000260517 | D9: =B9/$B$3*100 -> 100.96696 | E9: =C9/$C$3*100 -> 97.744336 | G9: 0.00206383 | H9: 0.000317838 | I9: =G9/$G$3*100 -> 114.35862 | J9: =H9/$H$3*100 -> 114.40964 | L9: 0.00194733 | M9: 0.000254245 | N9: =L9/$L$3*100 -> 114.68847 | O9: =M9/$M$3*100 -> 108.25616 | Q9: 0.00200308 | R9: 0.000298171 | S9: =Q9/$Q$3*100 -> 113.2125 | T9: =R9/$R$3*100 -> 109.04519 | V9: 0.00157417 | W9: 0.000233929 | X9: =V9/$V$3*100 -> 105.61851 | Y9: =W9/$W$3*100 -> 101.89477 | AA9: =AVERAGE(B9,G9,L9,Q9,V9) -> 0.001869776 | AB9: =AVERAGE(C9,H9,M9,R9,W9) -> 0.00027294 | AD9: =AVERAGE(D9,I9,N9,S9,X9) -> 109.76901 | AE9: =AVERAGE(E9,J9,O9,T9,Y9) -> 106.27002 | AG9: =_xlfn.STDEV.P(D9,I9,N9,S9,X9) -> 5.5104618 | AH9: =_xlfn.STDEV.P(E9,J9,O9,T9,Y9) -> 5.826318
A10: 49.6718 | B10: 0.00176274 | C10: 0.00026015 | D10: =B10/$B$3*100 -> 101.09715 | E10: =C10/$C$3*100 -> 97.606639 | G10: 0.00213009 | H10: 0.000329226 | I10: =G10/$G$3*100 -> 118.03014 | J10: =H10/$H$3*100 -> 118.50889 | L10: 0.00198726 | M10: 0.000258415 | N10: =L10/$L$3*100 -> 117.04016 | O10: =M10/$M$3*100 -> 110.03172 | Q10: 0.00203899 | R10: 0.000300926 | S10: =Q10/$Q$3*100 -> 115.2421 | T10: =R10/$R$3*100 -> 110.05274 | V10: 0.00158686 | W10: 0.000237305 | X10: =V10/$V$3*100 -> 106.46994 | Y10: =W10/$W$3*100 -> 103.36529 | AA10: =AVERAGE(B10,G10,L10,Q10,V10) -> 0.001901188 | AB10: =AVERAGE(C10,H10,M10,R10,W10) -> 0.0002772044 | AD10: =AVERAGE(D10,I10,N10,S10,X10) -> 111.5759 | AE10: =AVERAGE(E10,J10,O10,T10,Y10) -> 107.91306 | AG10: =_xlfn.STDEV.P(D10,I10,N10,S10,X10) -> 6.645772 | AH10: =_xlfn.STDEV.P(E10,J10,O10,T10,Y10) -> 7.0461781
A11: 55.9278 | B11: 0.00176503 | C11: 0.000259314 | D11: =B11/$B$3*100 -> 101.22849 | E11: =C11/$C$3*100 -> 97.292977 | G11: 0.00218657 | H11: 0.00033977 | I11: =G11/$G$3*100 -> 121.15975 | J11: =H11/$H$3*100 -> 122.30433 | L11: 0.00202763 | M11: 0.000262689 | N11: =L11/$L$3*100 -> 119.41776 | O11: =M11/$M$3*100 -> 111.85157 | Q11: 0.00207477 | R11: 0.000305409 | S11: =Q11/$Q$3*100 -> 117.26436 | T11: =R11/$R$3*100 -> 111.69223 | V11: 0.00160111 | W11: 0.000236308 | X11: =V11/$V$3*100 -> 107.42604 | Y11: =W11/$W$3*100 -> 102.93102 | AA11: =AVERAGE(B11,G11,L11,Q11,V11) -> 0.001931022 | AB11: =AVERAGE(C11,H11,M11,R11,W11) -> 0.000280698 | AD11: =AVERAGE(D11,I11,N11,S11,X11) -> 113.29928 | AE11: =AVERAGE(E11,J11,O11,T11,Y11) -> 109.21443 | AG11: =_xlfn.STDEV.P(D11,I11,N11,S11,X11) -> 7.6830151 | AH11: =_xlfn.STDEV.P(E11,J11,O11,T11,Y11) -> 8.5561892
A12: 62.0311 | B12: 0.00176604 | C12: 0.000258423 | D12: =B12/$B$3*100 -> 101.28641 | E12: =C12/$C$3*100 -> 96.95868 | G12: 0.00223751 | H12: 0.000346116 | I12: =G12/$G$3*100 -> 123.98238 | J12: =H12/$H$3*100 -> 124.58865 | L12: 0.00207181 | M12: 0.000263355 | N12: =L12/$L$3*100 -> 122.01975 | O12: =M12/$M$3*100 -> 112.13515 | Q12: 0.00212078 | R12: 0.00030887 | S12: =Q12/$Q$3*100 -> 119.86481 | T12: =R12/$R$3*100 -> 112.95796 | V12: 0.00160842 | W12: 0.000241818 | X12: =V12/$V$3*100 -> 107.91651 | Y12: =W12/$W$3*100 -> 105.33106 | AA12: =AVERAGE(B12,G12,L12,Q12,V12) -> 0.001960912 | AB12: =AVERAGE(C12,H12,M12,R12,W12) -> 0.0002837164 | AD12: =AVERAGE(D12,I12,N12,S12,X12) -> 115.01397 | AE12: =AVERAGE(E12,J12,O12,T12,Y12) -> 110.3943 | AG12: =_xlfn.STDEV.P(D12,I12,N12,S12,X12) -> 8.8528393 | AH12: =_xlfn.STDEV.P(E12,J12,O12,T12,Y12) -> 9.1349313
A13: 68.2132 | B13: 0.00176439 | C13: 0.000259515 | D13: =B13/$B$3*100 -> 101.19178 | E13: =C13/$C$3*100 -> 97.368391 | G13: 0.00229033 | H13: 0.000354202 | I13: =G13/$G$3*100 -> 126.90918 | J13: =H13/$H$3*100 -> 127.49931 | L13: 0.00211146 | M13: 0.000269665 | N13: =L13/$L$3*100 -> 124.35495 | O13: =M13/$M$3*100 -> 114.82191 | Q13: 0.00215946 | R13: 0.000312877 | S13: =Q13/$Q$3*100 -> 122.05097 | T13: =R13/$R$3*100 -> 114.42338 | V13: 0.00162488 | W13: 0.000241875 | X13: =V13/$V$3*100 -> 109.02089 | Y13: =W13/$W$3*100 -> 105.35589 | AA13: =AVERAGE(B13,G13,L13,Q13,V13) -> 0.001990104 | AB13: =AVERAGE(C13,H13,M13,R13,W13) -> 0.0002876268 | AD13: =AVERAGE(D13,I13,N13,S13,X13) -> 116.70555 | AE13: =AVERAGE(E13,J13,O13,T13,Y13) -> 111.89378 | AG13: =_xlfn.STDEV.P(D13,I13,N13,S13,X13) -> 9.9089053 | AH13: =_xlfn.STDEV.P(E13,J13,O13,T13,Y13) -> 10.121623
A14: 74.4616 | B14: 0.00176382 | C14: 0.000258695 | D14: =B14/$B$3*100 -> 101.15909 | E14: =C14/$C$3*100 -> 97.060733 | G14: 0.00236365 | H14: 0.000366501 | I14: =G14/$G$3*100 -> 130.97191 | J14: =H14/$H$3*100 -> 131.92648 | L14: 0.00215656 | M14: 0.000269456 | N14: =L14/$L$3*100 -> 127.01113 | O14: =M14/$M$3*100 -> 114.73292 | Q14: 0.00219489 | R14: 0.000316865 | S14: =Q14/$Q$3*100 -> 124.05344 | T14: =R14/$R$3*100 -> 115.88185 | V14: 0.00164139 | W14: 0.000245488 | X14: =V14/$V$3*100 -> 110.12862 | Y14: =W14/$W$3*100 -> 106.92964 | AA14: =AVERAGE(B14,G14,L14,Q14,V14) -> 0.002024062 | AB14: =AVERAGE(C14,H14,M14,R14,W14) -> 0.000291401 | AD14: =AVERAGE(D14,I14,N14,S14,X14) -> 118.66484 | AE14: =AVERAGE(E14,J14,O14,T14,Y14) -> 113.30632 | AG14: =_xlfn.STDEV.P(D14,I14,N14,S14,X14) -> 11.220337 | AH14: =_xlfn.STDEV.P(E14,J14,O14,T14,Y14) -> 11.488778
... A109: 692.197 | B109: 0.00110615 | C109: 0.000195 | D109: =B109/$B$3*100 -> 63.440219 | E109: =C109/$C$3*100 -> 73.16277 | G109: 0.00224829 | H109: 0.000362711 | I109: =G109/$G$3*100 -> 124.57971 | J109: =H109/$H$3*100 -> 130.56222 | L109: 0.00188373 | M109: 0.000259645 | N109: =L109/$L$3*100 -> 110.94274 | O109: =M109/$M$3*100 -> 110.55545 | Q109: 0.00208331 | R109: 0.000331212 | S109: =Q109/$Q$3*100 -> 117.74703 | T109: =R109/$R$3*100 -> 121.12874 | V109: 0.0022416 | W109: 0.000380834 | X109: =V109/$V$3*100 -> 150.39955 | Y109: =W109/$W$3*100 -> 165.88364 | AA109: =AVERAGE(B109,G109,L109,Q109,V109) -> 0.001912616 | AB109: =AVERAGE(C109,H109,M109,R109,W109) -> 0.0003058804 | AD109: =AVERAGE(D109,I109,N109,S109,X109) -> 113.42185 | AE109: =AVERAGE(E109,J109,O109,T109,Y109) -> 120.25856 | AG109: =_xlfn.STDEV.P(D109,I109,N109,S109,X109) -> 28.336777 | AH109: =_xlfn.STDEV.P(E109,J109,O109,T109,Y109) -> 30.002448

Sheet 1250 P+ 24 hpi
A1: Time | B1: Storage modulus | C1: Loss modulus | D1: Percent storage modulus | E1: Percent loss modulus | G1: Storage modulus | H1: Loss modulus | L1: Storage modulus | M1: Loss modulus | Q1: Average storage modulus | R1: Average loss modulus | T1: Average storage modulus/initial | U1: Average loss modulus/initial | W1: SD G' | X1: SD G''
A2: s | B2: MPa | C2: MPa | D2: MPa | E2: MPa | G2: MPa | H2: MPa | L2: MPa | M2: MPa | Q2: MPa | R2: MPa | T2: MPa | U2: MPa | W2: MPa | X2: MPa
A3: 6.26964 | B3: 0.00148166 | C3: 0.000230831 | D3: =B3/$B$3*100 -> 100 | E3: =C3/$C$3*100 -> 100 | Q3: =AVERAGE(B3,G3,L3) -> 0.00148166 | R3: =AVERAGE(C3,H3,M3) -> 0.000230831 | T3: =AVERAGE(D3,I3,N3) -> 100 | U3: =AVERAGE(E3,J3,O3) -> 100 | W3: =_xlfn.STDEV.P(D3,I3,N3) -> 0 | X3: =_xlfn.STDEV.P(E3,J3,O3) -> 0
A4: 12.3698 | B4: 0.00149146 | C4: 0.000229428 | D4: =B4/$B$3*100 -> 100.66142 | E4: =C4/$C$3*100 -> 99.392196 | Q4: =AVERAGE(B4,G4,L4) -> 0.00149146 | R4: =AVERAGE(C4,H4,M4) -> 0.000229428 | T4: =AVERAGE(D4,I4,N4) -> 100.66142 | U4: =AVERAGE(E4,J4,O4) -> 99.392196 | W4: =_xlfn.STDEV.P(D4,I4,N4) -> 0 | X4: =_xlfn.STDEV.P(E4,J4,O4) -> 0
A5: 18.654 | B5: 0.00150112 | C5: 0.000229363 | D5: =B5/$B$3*100 -> 101.31339 | E5: =C5/$C$3*100 -> 99.364037 | Q5: =AVERAGE(B5,G5,L5) -> 0.00150112 | R5: =AVERAGE(C5,H5,M5) -> 0.000229363 | T5: =AVERAGE(D5,I5,N5) -> 101.31339 | U5: =AVERAGE(E5,J5,O5) -> 99.364037 | W5: =_xlfn.STDEV.P(D5,I5,N5) -> 0 | X5: =_xlfn.STDEV.P(E5,J5,O5) -> 0
A6: 24.7796 | B6: 0.00151104 | C6: 0.000229311 | D6: =B6/$B$3*100 -> 101.98291 | E6: =C6/$C$3*100 -> 99.34151 | Q6: =AVERAGE(B6,G6,L6) -> 0.00151104 | R6: =AVERAGE(C6,H6,M6) -> 0.000229311 | T6: =AVERAGE(D6,I6,N6) -> 101.98291 | U6: =AVERAGE(E6,J6,O6) -> 99.34151 | W6: =_xlfn.STDEV.P(D6,I6,N6) -> 0 | X6: =_xlfn.STDEV.P(E6,J6,O6) -> 0
A7: 31.0945 | B7: 0.00152084 | C7: 0.000230283 | D7: =B7/$B$3*100 -> 102.64433 | E7: =C7/$C$3*100 -> 99.762597 | Q7: =AVERAGE(B7,G7,L7) -> 0.00152084 | R7: =AVERAGE(C7,H7,M7) -> 0.000230283 | T7: =AVERAGE(D7,I7,N7) -> 102.64433 | U7: =AVERAGE(E7,J7,O7) -> 99.762597 | W7: =_xlfn.STDEV.P(D7,I7,N7) -> 0 | X7: =_xlfn.STDEV.P(E7,J7,O7) -> 0
A8: 37.1619 | B8: 0.00152951 | C8: 0.000231059 | D8: =B8/$B$3*100 -> 103.22949 | E8: =C8/$C$3*100 -> 100.09877 | Q8: =AVERAGE(B8,G8,L8) -> 0.00152951 | R8: =AVERAGE(C8,H8,M8) -> 0.000231059 | T8: =AVERAGE(D8,I8,N8) -> 103.22949 | U8: =AVERAGE(E8,J8,O8) -> 100.09877 | W8: =_xlfn.STDEV.P(D8,I8,N8) -> 0 | X8: =_xlfn.STDEV.P(E8,J8,O8) -> 0
A9: 43.4417 | B9: 0.00153706 | C9: 0.000231689 | D9: =B9/$B$3*100 -> 103.73905 | E9: =C9/$C$3*100 -> 100.3717 | Q9: =AVERAGE(B9,G9,L9) -> 0.00153706 | R9: =AVERAGE(C9,H9,M9) -> 0.000231689 | T9: =AVERAGE(D9,I9,N9) -> 103.73905 | U9: =AVERAGE(E9,J9,O9) -> 100.3717 | W9: =_xlfn.STDEV.P(D9,I9,N9) -> 0 | X9: =_xlfn.STDEV.P(E9,J9,O9) -> 0
A10: 49.6718 | B10: 0.00154532 | C10: 0.000232328 | D10: =B10/$B$3*100 -> 104.29653 | E10: =C10/$C$3*100 -> 100.64853 | Q10: =AVERAGE(B10,G10,L10) -> 0.00154532 | R10: =AVERAGE(C10,H10,M10) -> 0.000232328 | T10: =AVERAGE(D10,I10,N10) -> 104.29653 | U10: =AVERAGE(E10,J10,O10) -> 100.64853 | W10: =_xlfn.STDEV.P(D10,I10,N10) -> 0 | X10: =_xlfn.STDEV.P(E10,J10,O10) -> 0
A11: 55.9278 | B11: 0.00155358 | C11: 0.000233114 | D11: =B11/$B$3*100 -> 104.85402 | E11: =C11/$C$3*100 -> 100.98904 | Q11: =AVERAGE(B11,G11,L11) -> 0.00155358 | R11: =AVERAGE(C11,H11,M11) -> 0.000233114 | T11: =AVERAGE(D11,I11,N11) -> 104.85402 | U11: =AVERAGE(E11,J11,O11) -> 100.98904 | W11: =_xlfn.STDEV.P(D11,I11,N11) -> 0 | X11: =_xlfn.STDEV.P(E11,J11,O11) -> 0
A12: 62.0311 | B12: 0.00156115 | C12: 0.000233201 | D12: =B12/$B$3*100 -> 105.36493 | E12: =C12/$C$3*100 -> 101.02673 | Q12: =AVERAGE(B12,G12,L12) -> 0.00156115 | R12: =AVERAGE(C12,H12,M12) -> 0.000233201 | T12: =AVERAGE(D12,I12,N12) -> 105.36493 | U12: =AVERAGE(E12,J12,O12) -> 101.02673 | W12: =_xlfn.STDEV.P(D12,I12,N12) -> 0 | X12: =_xlfn.STDEV.P(E12,J12,O12) -> 0
A13: 68.2132 | B13: 0.00156797 | C13: 0.00023394 | D13: =B13/$B$3*100 -> 105.82522 | E13: =C13/$C$3*100 -> 101.34687 | Q13: =AVERAGE(B13,G13,L13) -> 0.00156797 | R13: =AVERAGE(C13,H13,M13) -> 0.00023394 | T13: =AVERAGE(D13,I13,N13) -> 105.82522 | U13: =AVERAGE(E13,J13,O13) -> 101.34687 | W13: =_xlfn.STDEV.P(D13,I13,N13) -> 0 | X13: =_xlfn.STDEV.P(E13,J13,O13) -> 0
A14: 74.4616 | B14: 0.00157923 | C14: 0.000234354 | D14: =B14/$B$3*100 -> 106.58518 | E14: =C14/$C$3*100 -> 101.52622 | Q14: =AVERAGE(B14,G14,L14) -> 0.00157923 | R14: =AVERAGE(C14,H14,M14) -> 0.000234354 | T14: =AVERAGE(D14,I14,N14) -> 106.58518 | U14: =AVERAGE(E14,J14,O14) -> 101.52622 | W14: =_xlfn.STDEV.P(D14,I14,N14) -> 0 | X14: =_xlfn.STDEV.P(E14,J14,O14) -> 0
... A109: 692.197 | B109: 0.00103611 | C109: 0.000183126 | D109: =B109/$B$3*100 -> 69.928999 | E109: =C109/$C$3*100 -> 79.333365 | Q109: =AVERAGE(B109,G109,L109) -> 0.00103611 | R109: =AVERAGE(C109,H109,M109) -> 0.000183126 | T109: =AVERAGE(D109,I109,N109) -> 69.928999 | U109: =AVERAGE(E109,J109,O109) -> 79.333365 | W109: =_xlfn.STDEV.P(D109,I109,N109) -> 0 | X109: =_xlfn.STDEV.P(E109,J109,O109) -> 0

Sheet 1480 P- 24 hpi
A1: Time | B1: Storage modulus | C1: Loss modulus | D1: Percent storage modulus | E1: Percent loss modulus | G1: Storage modulus | H1: Loss modulus | I1: Percent storage modulus | J1: Percent loss modulus | L1: Storage modulus | M1: Loss modulus | N1: Percent storage modulus | O1: Percent loss modulus | Q1: Average storage modulus | R1: Average loss modulus | T1: Average storage modulus/initial | U1: Average loss modulus/initial | W1: SD G' | X1: SD G''
A2: s | B2: MPa | C2: MPa | D2: MPa | E2: MPa | G2: MPa | H2: MPa | I2: MPa | J2: MPa | L2: MPa | M2: MPa | N2: MPa | O2: MPa | Q2: MPa | R2: MPa | T2: MPa | U2: MPa | W2: MPa | X2: MPa
A3: 6.1609 | B3: 0.000775578 | C3: 0.000188806 | D3: =B3/$B$3*100 -> 100 | E3: =C3/$C$3*100 -> 100 | G3: 0.000692331 | H3: 0.000162958 | I3: =G3/$G$3*100 -> 100 | J3: =H3/$H$3*100 -> 100 | L3: 0.00113937 | M3: 0.000196376 | N3: =L3/$L$3*100 -> 100 | O3: =M3/$M$3*100 -> 100 | Q3: =AVERAGE(B3,G3,L3) -> 0.000869093 | R3: =AVERAGE(C3,H3,M3) -> 0.00018271333 | T3: =AVERAGE(D3,I3,N3) -> 100 | U3: =AVERAGE(E3,J3,O3) -> 100 | W3: =_xlfn.STDEV.P(D3,I3,N3) -> 0 | X3: =_xlfn.STDEV.P(E3,J3,O3) -> 0
A4: 12.3779 | B4: 0.00079058 | C4: 0.000187678 | D4: =B4/$B$3*100 -> 101.9343 | E4: =C4/$C$3*100 -> 99.402561 | G4: 0.000712784 | H4: 0.000165962 | I4: =G4/$G$3*100 -> 102.95422 | J4: =H4/$H$3*100 -> 101.84342 | L4: 0.00115877 | M4: 0.000196439 | N4: =L4/$L$3*100 -> 101.7027 | O4: =M4/$M$3*100 -> 100.03208 | Q4: =AVERAGE(B4,G4,L4) -> 0.000887378 | R4: =AVERAGE(C4,H4,M4) -> 0.00018335967 | T4: =AVERAGE(D4,I4,N4) -> 102.19707 | U4: =AVERAGE(E4,J4,O4) -> 100.42602 | W4: =_xlfn.STDEV.P(D4,I4,N4) -> 0.54367117 | X4: =_xlfn.STDEV.P(E4,J4,O4) -> 1.0346783
A5: 18.5842 | B5: 0.000809264 | C5: 0.000187216 | D5: =B5/$B$3*100 -> 104.34334 | E5: =C5/$C$3*100 -> 99.157866 | G5: 0.00073182 | H5: 0.000169586 | I5: =G5/$G$3*100 -> 105.70377 | J5: =H5/$H$3*100 -> 104.06731 | L5: 0.00117477 | M5: 0.000199432 | N5: =L5/$L$3*100 -> 103.10698 | O5: =M5/$M$3*100 -> 101.5562 | Q5: =AVERAGE(B5,G5,L5) -> 0.00090528467 | R5: =AVERAGE(C5,H5,M5) -> 0.00018541133 | T5: =AVERAGE(D5,I5,N5) -> 104.3847 | U5: =AVERAGE(E5,J5,O5) -> 101.59379 | W5: =_xlfn.STDEV.P(D5,I5,N5) -> 1.0605402 | X5: =_xlfn.STDEV.P(E5,J5,O5) -> 2.0044467
A6: 24.8146 | B6: 0.00082186 | C6: 0.000190598 | D6: =B6/$B$3*100 -> 105.96742 | E6: =C6/$C$3*100 -> 100.94912 | G6: 0.000752957 | H6: 0.00016829 | I6: =G6/$G$3*100 -> 108.75679 | J6: =H6/$H$3*100 -> 103.27201 | L6: 0.00119839 | M6: 0.000200621 | N6: =L6/$L$3*100 -> 105.18006 | O6: =M6/$M$3*100 -> 102.16167 | Q6: =AVERAGE(B6,G6,L6) -> 0.00092440233 | R6: =AVERAGE(C6,H6,M6) -> 0.000186503 | T6: =AVERAGE(D6,I6,N6) -> 106.63476 | U6: =AVERAGE(E6,J6,O6) -> 102.1276 | W6: =_xlfn.STDEV.P(D6,I6,N6) -> 1.5345505 | X6: =_xlfn.STDEV.P(E6,J6,O6) -> 0.94862033
A7: 30.9555 | B7: 0.000835392 | C7: 0.000192172 | D7: =B7/$B$3*100 -> 107.71218 | E7: =C7/$C$3*100 -> 101.78278 | G7: 0.00077566 | H7: 0.000174866 | I7: =G7/$G$3*100 -> 112.03601 | J7: =H7/$H$3*100 -> 107.3074 | L7: 0.00121623 | M7: 0.000205049 | N7: =L7/$L$3*100 -> 106.74583 | O7: =M7/$M$3*100 -> 104.41653 | Q7: =AVERAGE(B7,G7,L7) -> 0.00094242733 | R7: =AVERAGE(C7,H7,M7) -> 0.00019069567 | T7: =AVERAGE(D7,I7,N7) -> 108.83134 | U7: =AVERAGE(E7,J7,O7) -> 104.50224 | W7: =_xlfn.STDEV.P(D7,I7,N7) -> 2.3001256 | X7: =_xlfn.STDEV.P(E7,J7,O7) -> 2.2562316
A8: 37.1939 | B8: 0.00085029 | C8: 0.000193931 | D8: =B8/$B$3*100 -> 109.63307 | E8: =C8/$C$3*100 -> 102.71443 | G8: 0.000793606 | H8: 0.000179096 | I8: =G8/$G$3*100 -> 114.62812 | J8: =H8/$H$3*100 -> 109.90317 | L8: 0.00123221 | M8: 0.000204705 | N8: =L8/$L$3*100 -> 108.14836 | O8: =M8/$M$3*100 -> 104.24135 | Q8: =AVERAGE(B8,G8,L8) -> 0.000958702 | R8: =AVERAGE(C8,H8,M8) -> 0.00019257733 | T8: =AVERAGE(D8,I8,N8) -> 110.80318 | U8: =AVERAGE(E8,J8,O8) -> 105.61965 | W8: =_xlfn.STDEV.P(D8,I8,N8) -> 2.7717239 | X8: =_xlfn.STDEV.P(E8,J8,O8) -> 3.0923846
A9: 43.328 | B9: 0.000868979 | C9: 0.000195517 | D9: =B9/$B$3*100 -> 112.04276 | E9: =C9/$C$3*100 -> 103.55444 | G9: 0.000817475 | H9: 0.000180737 | I9: =G9/$G$3*100 -> 118.07575 | J9: =H9/$H$3*100 -> 110.91017 | L9: 0.00124592 | M9: 0.000206662 | N9: =L9/$L$3*100 -> 109.35166 | O9: =M9/$M$3*100 -> 105.23791 | Q9: =AVERAGE(B9,G9,L9) -> 0.000977458 | R9: =AVERAGE(C9,H9,M9) -> 0.00019430533 | T9: =AVERAGE(D9,I9,N9) -> 113.15672 | U9: =AVERAGE(E9,J9,O9) -> 106.56751 | W9: =_xlfn.STDEV.P(D9,I9,N9) -> 3.6476577 | X9: =_xlfn.STDEV.P(E9,J9,O9) -> 3.1466985
A10: 49.5092 | B10: 0.000884304 | C10: 0.000197553 | D10: =B10/$B$3*100 -> 114.01871 | E10: =C10/$C$3*100 -> 104.6328 | G10: 0.000843112 | H10: 0.000185434 | I10: =G10/$G$3*100 -> 121.77874 | J10: =H10/$H$3*100 -> 113.79251 | L10: 0.00126214 | M10: 0.000209103 | N10: =L10/$L$3*100 -> 110.77525 | O10: =M10/$M$3*100 -> 106.48093 | Q10: =AVERAGE(B10,G10,L10) -> 0.00099651867 | R10: =AVERAGE(C10,H10,M10) -> 0.00019736333 | T10: =AVERAGE(D10,I10,N10) -> 115.52423 | U10: =AVERAGE(E10,J10,O10) -> 108.30208 | W10: =_xlfn.STDEV.P(D10,I10,N10) -> 4.6165766 | X10: =_xlfn.STDEV.P(E10,J10,O10) -> 3.9549562
A11: 55.8187 | B11: 0.000897631 | C11: 0.00019857 | D11: =B11/$B$3*100 -> 115.73704 | E11: =C11/$C$3*100 -> 105.17145 | G11: 0.000866817 | H11: 0.000188898 | I11: =G11/$G$3*100 -> 125.20268 | J11: =H11/$H$3*100 -> 115.91821 | L11: 0.0012787 | M11: 0.000214203 | N11: =L11/$L$3*100 -> 112.22869 | O11: =M11/$M$3*100 -> 109.07799 | Q11: =AVERAGE(B11,G11,L11) -> 0.0010143827 | R11: =AVERAGE(C11,H11,M11) -> 0.000200557 | T11: =AVERAGE(D11,I11,N11) -> 117.7228 | U11: =AVERAGE(E11,J11,O11) -> 110.05588 | W11: =_xlfn.STDEV.P(D11,I11,N11) -> 5.4795742 | X11: =_xlfn.STDEV.P(E11,J11,O11) -> 4.4415049
A12: 61.9484 | B12: 0.000917967 | C12: 0.000201742 | D12: =B12/$B$3*100 -> 118.35908 | E12: =C12/$C$3*100 -> 106.85148 | G12: 0.000883826 | H12: 0.000192679 | I12: =G12/$G$3*100 -> 127.65946 | J12: =H12/$H$3*100 -> 118.23844 | L12: 0.00129266 | M12: 0.000207999 | N12: =L12/$L$3*100 -> 113.45393 | O12: =M12/$M$3*100 -> 105.91875 | Q12: =AVERAGE(B12,G12,L12) -> 0.0010314843 | R12: =AVERAGE(C12,H12,M12) -> 0.00020080667 | T12: =AVERAGE(D12,I12,N12) -> 119.82416 | U12: =AVERAGE(E12,J12,O12) -> 110.33622 | W12: =_xlfn.STDEV.P(D12,I12,N12) -> 5.8911861 | X12: =_xlfn.STDEV.P(E12,J12,O12) -> 5.6006727
A13: 68.2946 | B13: 0.00093604 | C13: 0.000203941 | D13: =B13/$B$3*100 -> 120.68934 | E13: =C13/$C$3*100 -> 108.01616 | G13: 0.000911075 | H13: 0.000194015 | I13: =G13/$G$3*100 -> 131.59529 | J13: =H13/$H$3*100 -> 119.05828 | L13: 0.00130678 | M13: 0.000213594 | N13: =L13/$L$3*100 -> 114.69321 | O13: =M13/$M$3*100 -> 108.76787 | Q13: =AVERAGE(B13,G13,L13) -> 0.0010512983 | R13: =AVERAGE(C13,H13,M13) -> 0.00020385 | T13: =AVERAGE(D13,I13,N13) -> 122.32595 | U13: =AVERAGE(E13,J13,O13) -> 111.94744 | W13: =_xlfn.STDEV.P(D13,I13,N13) -> 6.9966166 | X13: =_xlfn.STDEV.P(E13,J13,O13) -> 5.0374822
A14: 74.3768 | B14: 0.000953445 | C14: 0.000205575 | D14: =B14/$B$3*100 -> 122.93348 | E14: =C14/$C$3*100 -> 108.8816 | G14: 0.000931952 | H14: 0.000199596 | I14: =G14/$G$3*100 -> 134.61076 | J14: =H14/$H$3*100 -> 122.48309 | L14: 0.0013231 | M14: 0.000217765 | N14: =L14/$L$3*100 -> 116.12558 | O14: =M14/$M$3*100 -> 110.89186 | Q14: =AVERAGE(B14,G14,L14) -> 0.001069499 | R14: =AVERAGE(C14,H14,M14) -> 0.00020764533 | T14: =AVERAGE(D14,I14,N14) -> 124.5566 | U14: =AVERAGE(E14,J14,O14) -> 114.08552 | W14: =_xlfn.STDEV.P(D14,I14,N14) -> 7.6333202 | X14: =_xlfn.STDEV.P(E14,J14,O14) -> 5.9944267
... A109: 692.554 | B109: 0.000939879 | C109: 0.000225888 | D109: =B109/$B$3*100 -> 121.18433 | E109: =C109/$C$3*100 -> 119.64027 | G109: 0.000962634 | H109: 0.000242201 | I109: =G109/$G$3*100 -> 139.04245 | J109: =H109/$H$3*100 -> 148.62787 | L109: 0.000925686 | M109: 0.000186558 | N109: =L109/$L$3*100 -> 81.245425 | O109: =M109/$M$3*100 -> 95.000407 | Q109: =AVERAGE(B109,G109,L109) -> 0.000942733 | R109: =AVERAGE(C109,H109,M109) -> 0.00021821567 | T109: =AVERAGE(D109,I109,N109) -> 113.82407 | U109: =AVERAGE(E109,J109,O109) -> 121.08951 | W109: =_xlfn.STDEV.P(D109,I109,N109) -> 24.162701 | X109: =_xlfn.STDEV.P(E109,J109,O109) -> 21.917289

Sheet 1009 24 hpi
A1: Time | B1: 10 mM Storage modulus | C1: 10 mM Loss modulus | D1: Percent storage modulus | E1: Percent loss modulus | G1: 1 mM Storage modulus | H1: 1 mM Loss modulus | I1: Percent storage modulus | J1: Percent loss modulus | L1: 0 mM Storage modulus | M1: 0 mM Loss modulus | N1: Percent storage modulus | O1: Percent loss modulus | Q1: Average storage modulus | R1: Average loss modulus | T1: Average storage modulus/initial | U1: Average loss modulus/initial | W1: SD G' | X1: SD G''
A2: s | B2: MPa | C2: MPa | D2: MPa | E2: MPa | G2: MPa | H2: MPa | I2: MPa | J2: MPa | L2: MPa | M2: MPa | N2: MPa | O2: MPa | Q2: MPa | R2: MPa | T2: MPa | U2: MPa | W2: MPa | X2: MPa
A3: 6.1609 | B3: 0.00319567 | C3: 0.000611701 | D3: =B3/$B$3*100 -> 100 | E3: =C3/$C$3*100 -> 100 | G3: 0.0014405 | H3: 0.000337509 | I3: =G3/$G$3*100 -> 100 | J3: =H3/$H$3*100 -> 100 | L3: 0.00387145 | M3: 0.000545296 | N3: =L3/$L$3*100 -> 100 | O3: =M3/$M$3*100 -> 100 | Q3: =AVERAGE(B3,G3,L3) -> 0.0028358733 | R3: =AVERAGE(C3,H3,M3) -> 0.00049816867 | T3: =AVERAGE(D3,I3,N3) -> 100 | U3: =AVERAGE(E3,J3,O3) -> 100 | W3: =_xlfn.STDEV.P(D3,I3,N3) -> 0 | X3: =_xlfn.STDEV.P(E3,J3,O3) -> 0
A4: 12.3779 | B4: 0.00321393 | C4: 0.000599077 | D4: =B4/$B$3*100 -> 100.5714 | E4: =C4/$C$3*100 -> 97.936247 | G4: 0.0014603 | H4: 0.000344362 | I4: =G4/$G$3*100 -> 101.37452 | J4: =H4/$H$3*100 -> 102.03046 | L4: 0.00393997 | M4: 0.000534956 | N4: =L4/$L$3*100 -> 101.76988 | O4: =M4/$M$3*100 -> 98.103782 | Q4: =AVERAGE(B4,G4,L4) -> 0.0028714 | R4: =AVERAGE(C4,H4,M4) -> 0.00049279833 | T4: =AVERAGE(D4,I4,N4) -> 101.2386 | U4: =AVERAGE(E4,J4,O4) -> 99.356831 | W4: =_xlfn.STDEV.P(D4,I4,N4) -> 0.49862851 | X4: =_xlfn.STDEV.P(E4,J4,O4) -> 1.8917811
A5: 18.5842 | B5: 0.00323919 | C5: 0.000602982 | D5: =B5/$B$3*100 -> 101.36184 | E5: =C5/$C$3*100 -> 98.57463 | G5: 0.00148298 | H5: 0.000345702 | I5: =G5/$G$3*100 -> 102.94898 | J5: =H5/$H$3*100 -> 102.42749 | L5: 0.00400217 | M5: 0.000553861 | N5: =L5/$L$3*100 -> 103.37651 | O5: =M5/$M$3*100 -> 101.57071 | Q5: =AVERAGE(B5,G5,L5) -> 0.0029081133 | R5: =AVERAGE(C5,H5,M5) -> 0.00050084833 | T5: =AVERAGE(D5,I5,N5) -> 102.56244 | U5: =AVERAGE(E5,J5,O5) -> 100.85761 | W5: =_xlfn.STDEV.P(D5,I5,N5) -> 0.86670991 | X5: =_xlfn.STDEV.P(E5,J5,O5) -> 1.6517696
A6: 24.8146 | B6: 0.00325872 | C6: 0.000602316 | D6: =B6/$B$3*100 -> 101.97298 | E6: =C6/$C$3*100 -> 98.465754 | G6: 0.00149985 | H6: 0.00034853 | I6: =G6/$G$3*100 -> 104.1201 | J6: =H6/$H$3*100 -> 103.26539 | L6: 0.00405234 | M6: 0.000551868 | N6: =L6/$L$3*100 -> 104.67241 | O6: =M6/$M$3*100 -> 101.20522 | Q6: =AVERAGE(B6,G6,L6) -> 0.00293697 | R6: =AVERAGE(C6,H6,M6) -> 0.00050090467 | T6: =AVERAGE(D6,I6,N6) -> 103.5885 | U6: =AVERAGE(E6,J6,O6) -> 100.97879 | W6: =_xlfn.STDEV.P(D6,I6,N6) -> 1.1643816 | X6: =_xlfn.STDEV.P(E6,J6,O6) -> 1.9659756
A7: 30.9555 | B7: 0.00327527 | C7: 0.000593577 | D7: =B7/$B$3*100 -> 102.49087 | E7: =C7/$C$3*100 -> 97.037115 | G7: 0.00151378 | H7: 0.000346311 | I7: =G7/$G$3*100 -> 105.08712 | J7: =H7/$H$3*100 -> 102.60793 | L7: 0.00410176 | M7: 0.000555703 | N7: =L7/$L$3*100 -> 105.94893 | O7: =M7/$M$3*100 -> 101.9085 | Q7: =AVERAGE(B7,G7,L7) -> 0.0029636033 | R7: =AVERAGE(C7,H7,M7) -> 0.00049853033 | T7: =AVERAGE(D7,I7,N7) -> 104.50898 | U7: =AVERAGE(E7,J7,O7) -> 100.51785 | W7: =_xlfn.STDEV.P(D7,I7,N7) -> 1.4697485 | X7: =_xlfn.STDEV.P(E7,J7,O7) -> 2.4777595
