Workbook

Sheet 1233 P- 72 hpi
A1: Time | B1: Storage modulus | C1: Loss modulus | D1: Percent storage modulus | E1: Percent loss modulus | G1: Storage modulus | H1: Loss modulus | I1: Percent storage modulus | J1: Percent loss modulus | L1: Storage modulus | M1: Loss modulus | N1: Percent storage modulus | O1: Percent loss modulus | Q1: Average storage modulus | R1: Average loss modulus | T1: Average storage modulus/initial | U1: Average loss modulus/initial | W1: SD G' | X1: SD G''
A2: s | B2: MPa | C2: MPa | D2: MPa | E2: MPa | G2: MPa | H2: MPa | I2: MPa | J2: MPa | L2: MPa | M2: MPa | N2: MPa | O2: MPa | Q2: MPa | R2: MPa | T2: MPa | U2: MPa | W2: MPa | X2: MPa
A3: 6.27187 | B3: 0.000832197 | C3: 0.000153708 | D3: =B3/$B$3*100 -> 100 | E3: =C3/$C$3*100 -> 100 | G3: 0.000848021 | H3: 0.000177818 | I3: =G3/$G$3*100 -> 100 | J3: =H3/$H$3*100 -> 100 | L3: 0.000985493 | M3: 0.00019363 | N3: =L3/$L$3*100 -> 100 | O3: =M3/$M$3*100 -> 100 | Q3: =AVERAGE(B3,G3,L3) -> 0.00088857033 | R3: =AVERAGE(C3,H3,M3) -> 0.000175052 | T3: =AVERAGE(D3,I3,N3) -> 100 | U3: =AVERAGE(E3,J3,O3) -> 100 | W3: =_xlfn.STDEV.P(D3,I3,N3) -> 0 | X3: =_xlfn.STDEV.P(E3,J3,O3) -> 0
A4: 12.4371 | B4: 0.000835237 | C4: 0.000153693 | D4: =B4/$B$3*100 -> 100.3653 | E4: =C4/$C$3*100 -> 99.990241 | G4: 0.000850912 | H4: 0.00017888 | I4: =G4/$G$3*100 -> 100.34091 | J4: =H4/$H$3*100 -> 100.59724 | L4: 0.000987997 | M4: 0.000193601 | N4: =L4/$L$3*100 -> 100.25409 | O4: =M4/$M$3*100 -> 99.985023 | Q4: =AVERAGE(B4,G4,L4) -> 0.000891382 | R4: =AVERAGE(C4,H4,M4) -> 0.00017539133 | T4: =AVERAGE(D4,I4,N4) -> 100.3201 | U4: =AVERAGE(E4,J4,O4) -> 100.19083 | W4: =_xlfn.STDEV.P(D4,I4,N4) -> 0.047727797 | X4: =_xlfn.STDEV.P(E4,J4,O4) -> 0.28737975
A5: 18.5455 | B5: 0.000836745 | C5: 0.000153005 | D5: =B5/$B$3*100 -> 100.54651 | E5: =C5/$C$3*100 -> 99.542639 | G5: 0.000852962 | H5: 0.000175807 | I5: =G5/$G$3*100 -> 100.58265 | J5: =H5/$H$3*100 -> 98.869068 | L5: 0.000993177 | M5: 0.000193643 | N5: =L5/$L$3*100 -> 100.77971 | O5: =M5/$M$3*100 -> 100.00671 | Q5: =AVERAGE(B5,G5,L5) -> 0.00089429467 | R5: =AVERAGE(C5,H5,M5) -> 0.00017415167 | T5: =AVERAGE(D5,I5,N5) -> 100.63629 | U5: =AVERAGE(E5,J5,O5) -> 99.472807 | W5: =_xlfn.STDEV.P(D5,I5,N5) -> 0.10248276 | X5: =_xlfn.STDEV.P(E5,J5,O5) -> 0.46705938
A6: 24.7914 | B6: 0.000839341 | C6: 0.000153585 | D6: =B6/$B$3*100 -> 100.85845 | E6: =C6/$C$3*100 -> 99.919978 | G6: 0.000856444 | H6: 0.000178353 | I6: =G6/$G$3*100 -> 100.99325 | J6: =H6/$H$3*100 -> 100.30087 | L6: 0.000996232 | M6: 0.000192496 | N6: =L6/$L$3*100 -> 101.08971 | O6: =M6/$M$3*100 -> 99.414347 | Q6: =AVERAGE(B6,G6,L6) -> 0.000897339 | R6: =AVERAGE(C6,H6,M6) -> 0.00017481133 | T6: =AVERAGE(D6,I6,N6) -> 100.98047 | U6: =AVERAGE(E6,J6,O6) -> 99.878398 | W6: =_xlfn.STDEV.P(D6,I6,N6) -> 0.094842306 | X6: =_xlfn.STDEV.P(E6,J6,O6) -> 0.36311357
A7: 31.107 | B7: 0.000841025 | C7: 0.000153344 | D7: =B7/$B$3*100 -> 101.06081 | E7: =C7/$C$3*100 -> 99.763187 | G7: 0.000859733 | H7: 0.000181831 | I7: =G7/$G$3*100 -> 101.3811 | J7: =H7/$H$3*100 -> 102.2568 | L7: 0.00100025 | M7: 0.000191343 | N7: =L7/$L$3*100 -> 101.49742 | O7: =M7/$M$3*100 -> 98.818881 | Q7: =AVERAGE(B7,G7,L7) -> 0.000900336 | R7: =AVERAGE(C7,H7,M7) -> 0.000175506 | T7: =AVERAGE(D7,I7,N7) -> 101.31311 | U7: =AVERAGE(E7,J7,O7) -> 100.27962 | W7: =_xlfn.STDEV.P(D7,I7,N7) -> 0.18461737 | X7: =_xlfn.STDEV.P(E7,J7,O7) -> 1.4502538
A8: 37.1924 | B8: 0.000843306 | C8: 0.000152706 | D8: =B8/$B$3*100 -> 101.3349 | E8: =C8/$C$3*100 -> 99.348115 | G8: 0.000860446 | H8: 0.000176234 | I8: =G8/$G$3*100 -> 101.46518 | J8: =H8/$H$3*100 -> 99.109202 | L8: 0.00100411 | M8: 0.000192569 | N8: =L8/$L$3*100 -> 101.88911 | O8: =M8/$M$3*100 -> 99.452048 | Q8: =AVERAGE(B8,G8,L8) -> 0.00090262067 | R8: =AVERAGE(C8,H8,M8) -> 0.00017383633 | T8: =AVERAGE(D8,I8,N8) -> 101.56306 | U8: =AVERAGE(E8,J8,O8) -> 99.303121 | W8: =_xlfn.STDEV.P(D8,I8,N8) -> 0.2366035 | X8: =_xlfn.STDEV.P(E8,J8,O8) -> 0.14353669
A9: 43.5262 | B9: 0.00084448 | C9: 0.00015195 | D9: =B9/$B$3*100 -> 101.47597 | E9: =C9/$C$3*100 -> 98.856273 | G9: 0.000861919 | H9: 0.000177898 | I9: =G9/$G$3*100 -> 101.63887 | J9: =H9/$H$3*100 -> 100.04499 | L9: 0.00100606 | M9: 0.000191449 | N9: =L9/$L$3*100 -> 102.08698 | O9: =M9/$M$3*100 -> 98.873625 | Q9: =AVERAGE(B9,G9,L9) -> 0.000904153 | R9: =AVERAGE(C9,H9,M9) -> 0.00017376567 | T9: =AVERAGE(D9,I9,N9) -> 101.73394 | U9: =AVERAGE(E9,J9,O9) -> 99.258296 | W9: =_xlfn.STDEV.P(D9,I9,N9) -> 0.25834012 | X9: =_xlfn.STDEV.P(E9,J9,O9) -> 0.55632171
A10: 49.6883 | B10: 0.000847212 | C10: 0.000151857 | D10: =B10/$B$3*100 -> 101.80426 | E10: =C10/$C$3*100 -> 98.795769 | G10: 0.000864847 | H10: 0.000178962 | I10: =G10/$G$3*100 -> 101.98415 | J10: =H10/$H$3*100 -> 100.64335 | L10: 0.00100969 | M10: 0.000189836 | N10: =L10/$L$3*100 -> 102.45532 | O10: =M10/$M$3*100 -> 98.040593 | Q10: =AVERAGE(B10,G10,L10) -> 0.00090724967 | R10: =AVERAGE(C10,H10,M10) -> 0.00017355167 | T10: =AVERAGE(D10,I10,N10) -> 102.08124 | U10: =AVERAGE(E10,J10,O10) -> 99.159905 | W10: =_xlfn.STDEV.P(D10,I10,N10) -> 0.27451761 | X10: =_xlfn.STDEV.P(E10,J10,O10) -> 1.0933248
A11: 55.8005 | B11: 0.000848699 | C11: 0.000151321 | D11: =B11/$B$3*100 -> 101.98294 | E11: =C11/$C$3*100 -> 98.447055 | G11: 0.00086593 | H11: 0.000178462 | I11: =G11/$G$3*100 -> 102.11186 | J11: =H11/$H$3*100 -> 100.36217 | L11: 0.00101228 | M11: 0.00019265 | N11: =L11/$L$3*100 -> 102.71813 | O11: =M11/$M$3*100 -> 99.49388 | Q11: =AVERAGE(B11,G11,L11) -> 0.00090896967 | R11: =AVERAGE(C11,H11,M11) -> 0.00017414433 | T11: =AVERAGE(D11,I11,N11) -> 102.27098 | U11: =AVERAGE(E11,J11,O11) -> 99.434368 | W11: =_xlfn.STDEV.P(D11,I11,N11) -> 0.3205357 | X11: =_xlfn.STDEV.P(E11,J11,O11) -> 0.78297312
A12: 62.1114 | B12: 0.00085013 | C12: 0.000151733 | D12: =B12/$B$3*100 -> 102.1549 | E12: =C12/$C$3*100 -> 98.715096 | G12: 0.000868415 | H12: 0.000179229 | I12: =G12/$G$3*100 -> 102.40489 | J12: =H12/$H$3*100 -> 100.79351 | L12: 0.00101522 | M12: 0.000192697 | N12: =L12/$L$3*100 -> 103.01646 | O12: =M12/$M$3*100 -> 99.518153 | Q12: =AVERAGE(B12,G12,L12) -> 0.000911255 | R12: =AVERAGE(C12,H12,M12) -> 0.000174553 | T12: =AVERAGE(D12,I12,N12) -> 102.52542 | U12: =AVERAGE(E12,J12,O12) -> 99.675586 | W12: =_xlfn.STDEV.P(D12,I12,N12) -> 0.36190837 | X12: =_xlfn.STDEV.P(E12,J12,O12) -> 0.85577944
A13: 68.3388 | B13: 0.000852038 | C13: 0.000151624 | D13: =B13/$B$3*100 -> 102.38417 | E13: =C13/$C$3*100 -> 98.644182 | G13: 0.000870546 | H13: 0.000178854 | I13: =G13/$G$3*100 -> 102.65618 | J13: =H13/$H$3*100 -> 100.58262 | L13: 0.0010173 | M13: 0.000190974 | N13: =L13/$L$3*100 -> 103.22752 | O13: =M13/$M$3*100 -> 98.628312 | Q13: =AVERAGE(B13,G13,L13) -> 0.00091329467 | R13: =AVERAGE(C13,H13,M13) -> 0.00017381733 | T13: =AVERAGE(D13,I13,N13) -> 102.75596 | U13: =AVERAGE(E13,J13,O13) -> 99.285037 | W13: =_xlfn.STDEV.P(D13,I13,N13) -> 0.35145062 | X13: =_xlfn.STDEV.P(E13,J13,O13) -> 0.917551
A14: 74.5085 | B14: 0.000852886 | C14: 0.000151607 | D14: =B14/$B$3*100 -> 102.48607 | E14: =C14/$C$3*100 -> 98.633123 | G14: 0.000870922 | H14: 0.000178617 | I14: =G14/$G$3*100 -> 102.70052 | J14: =H14/$H$3*100 -> 100.44934 | L14: 0.00101915 | M14: 0.000192639 | N14: =L14/$L$3*100 -> 103.41524 | O14: =M14/$M$3*100 -> 99.488199 | Q14: =AVERAGE(B14,G14,L14) -> 0.00091431933 | R14: =AVERAGE(C14,H14,M14) -> 0.00017428767 | T14: =AVERAGE(D14,I14,N14) -> 102.86728 | U14: =AVERAGE(E14,J14,O14) -> 99.523553 | W14: =_xlfn.STDEV.P(D14,I14,N14) -> 0.39723823 | X14: =_xlfn.STDEV.P(E14,J14,O14) -> 0.74188727
... A109: 692.494 | B109: 0.000813416 | C109: 0.000153578 | D109: =B109/$B$3*100 -> 97.743203 | E109: =C109/$C$3*100 -> 99.915424 | G109: 0.00083547 | H109: 0.000203946 | I109: =G109/$G$3*100 -> 98.519966 | J109: =H109/$H$3*100 -> 114.69368 | L109: 0.000933251 | M109: 0.000190485 | N109: =L109/$L$3*100 -> 94.698897 | O109: =M109/$M$3*100 -> 98.375768 | Q109: =AVERAGE(B109,G109,L109) -> 0.00086071233 | R109: =AVERAGE(C109,H109,M109) -> 0.00018266967 | T109: =AVERAGE(D109,I109,N109) -> 96.987355 | U109: =AVERAGE(E109,J109,O109) -> 104.32829 | W109: =_xlfn.STDEV.P(D109,I109,N109) -> 1.6489635 | X109: =_xlfn.STDEV.P(E109,J109,O109) -> 7.3563378

Sheet 1233 P+ 72 hpi
A1: Time | B1: Storage modulus | C1: Loss modulus | D1: Percent storage modulus | E1: Percent loss modulus | G1: Storage modulus | H1: Loss modulus | I1: Percent storage modulus | J1: Percent loss modulus | L1: Storage modulus | M1: Loss modulus | N1: Percent storage modulus | O1: Percent loss modulus | Q1: Average storage modulus | R1: Average loss modulus | T1: Average storage modulus/initial | U1: Average loss modulus/initial | W1: SD G' | X1: SD G''
A2: s | B2: MPa | C2: MPa | D2: MPa | E2: MPa | G2: MPa | H2: MPa | I2: MPa | J2: MPa | L2: MPa | M2: MPa | N2: MPa | O2: MPa | Q2: MPa | R2: MPa | T2: MPa | U2: MPa | W2: MPa | X2: MPa
A3: 6.27187 | B3: 0.00076262 | C3: 0.000174533 | D3: =B3/$B$3*100 -> 100 | E3: =C3/$C$3*100 -> 100 | G3: 0.000800817 | H3: 0.000174925 | I3: =G3/$G$3*100 -> 100 | J3: =H3/$H$3*100 -> 100 | Q3: =AVERAGE(B3,G3,L3) -> 0.0007817185 | R3: =AVERAGE(C3,H3,M3) -> 0.000174729 | T3: =AVERAGE(D3,I3,N3) -> 100 | U3: =AVERAGE(E3,J3,O3) -> 100 | W3: =_xlfn.STDEV.P(D3,I3,N3) -> 0 | X3: =_xlfn.STDEV.P(E3,J3,O3) -> 0
A4: 12.4371 | B4: 0.000760953 | C4: 0.000171136 | D4: =B4/$B$3*100 -> 99.781411 | E4: =C4/$C$3*100 -> 98.053663 | G4: 0.000803023 | H4: 0.000176 | I4: =G4/$G$3*100 -> 100.27547 | J4: =H4/$H$3*100 -> 100.61455 | Q4: =AVERAGE(B4,G4,L4) -> 0.000781988 | R4: =AVERAGE(C4,H4,M4) -> 0.000173568 | T4: =AVERAGE(D4,I4,N4) -> 100.02844 | U4: =AVERAGE(E4,J4,O4) -> 99.334106 | W4: =_xlfn.STDEV.P(D4,I4,N4) -> 0.24702861 | X4: =_xlfn.STDEV.P(E4,J4,O4) -> 1.2804429
A5: 18.5455 | B5: 0.00076039 | C5: 0.00016217 | D5: =B5/$B$3*100 -> 99.707587 | E5: =C5/$C$3*100 -> 92.916526 | G5: 0.000804707 | H5: 0.000173153 | I5: =G5/$G$3*100 -> 100.48575 | J5: =H5/$H$3*100 -> 98.986994 | Q5: =AVERAGE(B5,G5,L5) -> 0.0007825485 | R5: =AVERAGE(C5,H5,M5) -> 0.0001676615 | T5: =AVERAGE(D5,I5,N5) -> 100.09667 | U5: =AVERAGE(E5,J5,O5) -> 95.95176 | W5: =_xlfn.STDEV.P(D5,I5,N5) -> 0.38908346 | X5: =_xlfn.STDEV.P(E5,J5,O5) -> 3.0352343
A6: 24.7914 | B6: 0.00076267 | C6: 0.000158584 | D6: =B6/$B$3*100 -> 100.00656 | E6: =C6/$C$3*100 -> 90.8619 | G6: 0.0008057 | H6: 0.000171902 | I6: =G6/$G$3*100 -> 100.60975 | J6: =H6/$H$3*100 -> 98.271831 | Q6: =AVERAGE(B6,G6,L6) -> 0.000784185 | R6: =AVERAGE(C6,H6,M6) -> 0.000165243 | T6: =AVERAGE(D6,I6,N6) -> 100.30815 | U6: =AVERAGE(E6,J6,O6) -> 94.566865 | W6: =_xlfn.STDEV.P(D6,I6,N6) -> 0.30159797 | X6: =_xlfn.STDEV.P(E6,J6,O6) -> 3.7049654
A7: 31.107 | B7: 0.000763613 | C7: 0.000159213 | D7: =B7/$B$3*100 -> 100.13021 | E7: =C7/$C$3*100 -> 91.22229 | G7: 0.000806273 | H7: 0.000165535 | I7: =G7/$G$3*100 -> 100.6813 | J7: =H7/$H$3*100 -> 94.631985 | Q7: =AVERAGE(B7,G7,L7) -> 0.000784943 | R7: =AVERAGE(C7,H7,M7) -> 0.000162374 | T7: =AVERAGE(D7,I7,N7) -> 100.40576 | U7: =AVERAGE(E7,J7,O7) -> 92.927138 | W7: =_xlfn.STDEV.P(D7,I7,N7) -> 0.2755476 | X7: =_xlfn.STDEV.P(E7,J7,O7) -> 1.7048474
A8: 37.1924 | B8: 0.000766424 | C8: 0.000161487 | D8: =B8/$B$3*100 -> 100.49881 | E8: =C8/$C$3*100 -> 92.525196 | G8: 0.000809022 | H8: 0.000170565 | I8: =G8/$G$3*100 -> 101.02458 | J8: =H8/$H$3*100 -> 97.507503 | Q8: =AVERAGE(B8,G8,L8) -> 0.000787723 | R8: =AVERAGE(C8,H8,M8) -> 0.000166026 | T8: =AVERAGE(D8,I8,N8) -> 100.76169 | U8: =AVERAGE(E8,J8,O8) -> 95.01635 | W8: =_xlfn.STDEV.P(D8,I8,N8) -> 0.26288595 | X8: =_xlfn.STDEV.P(E8,J8,O8) -> 2.4911537
A9: 43.5262 | B9: 0.000769219 | C9: 0.000161586 | D9: =B9/$B$3*100 -> 100.86531 | E9: =C9/$C$3*100 -> 92.581919 | G9: 0.000809956 | H9: 0.000163986 | I9: =G9/$G$3*100 -> 101.14121 | J9: =H9/$H$3*100 -> 93.746463 | Q9: =AVERAGE(B9,G9,L9) -> 0.0007895875 | R9: =AVERAGE(C9,H9,M9) -> 0.000162786 | T9: =AVERAGE(D9,I9,N9) -> 101.00326 | U9: =AVERAGE(E9,J9,O9) -> 93.164191 | W9: =_xlfn.STDEV.P(D9,I9,N9) -> 0.13795155 | X9: =_xlfn.STDEV.P(E9,J9,O9) -> 0.58227208
A10: 49.6883 | B10: 0.000769757 | C10: 0.00015993 | D10: =B10/$B$3*100 -> 100.93585 | E10: =C10/$C$3*100 -> 91.633101 | G10: 0.000811893 | H10: 0.00016718 | I10: =G10/$G$3*100 -> 101.38309 | J10: =H10/$H$3*100 -> 95.572388 | Q10: =AVERAGE(B10,G10,L10) -> 0.000790825 | R10: =AVERAGE(C10,H10,M10) -> 0.000163555 | T10: =AVERAGE(D10,I10,N10) -> 101.15947 | U10: =AVERAGE(E10,J10,O10) -> 93.602745 | W10: =_xlfn.STDEV.P(D10,I10,N10) -> 0.2236174 | X10: =_xlfn.STDEV.P(E10,J10,O10) -> 1.9696436
A11: 55.8005 | B11: 0.000774624 | C11: 0.000166668 | D11: =B11/$B$3*100 -> 101.57405 | E11: =C11/$C$3*100 -> 95.493689 | G11: 0.000812634 | H11: 0.00016612 | I11: =G11/$G$3*100 -> 101.47562 | J11: =H11/$H$3*100 -> 94.966414 | Q11: =AVERAGE(B11,G11,L11) -> 0.000793629 | R11: =AVERAGE(C11,H11,M11) -> 0.000166394 | T11: =AVERAGE(D11,I11,N11) -> 101.52483 | U11: =AVERAGE(E11,J11,O11) -> 95.230052 | W11: =_xlfn.STDEV.P(D11,I11,N11) -> 0.049214669 | X11: =_xlfn.STDEV.P(E11,J11,O11) -> 0.26363735
A12: 62.1114 | B12: 0.000775444 | C12: 0.000164032 | D12: =B12/$B$3*100 -> 101.68157 | E12: =C12/$C$3*100 -> 93.983373 | G12: 0.000814137 | H12: 0.000163793 | I12: =G12/$G$3*100 -> 101.6633 | J12: =H12/$H$3*100 -> 93.63613 | Q12: =AVERAGE(B12,G12,L12) -> 0.0007947905 | R12: =AVERAGE(C12,H12,M12) -> 0.0001639125 | T12: =AVERAGE(D12,I12,N12) -> 101.67244 | U12: =AVERAGE(E12,J12,O12) -> 93.809751 | W12: =_xlfn.STDEV.P(D12,I12,N12) -> 0.0091350357 | X12: =_xlfn.STDEV.P(E12,J12,O12) -> 0.1736215
A13: 68.3388 | B13: 0.000779716 | C13: 0.000170517 | D13: =B13/$B$3*100 -> 102.24175 | E13: =C13/$C$3*100 -> 97.699002 | G13: 0.000813754 | H13: 0.000165885 | I13: =G13/$G$3*100 -> 101.61548 | J13: =H13/$H$3*100 -> 94.832071 | Q13: =AVERAGE(B13,G13,L13) -> 0.000796735 | R13: =AVERAGE(C13,H13,M13) -> 0.000168201 | T13: =AVERAGE(D13,I13,N13) -> 101.92861 | U13: =AVERAGE(E13,J13,O13) -> 96.265537 | W13: =_xlfn.STDEV.P(D13,I13,N13) -> 0.31313518 | X13: =_xlfn.STDEV.P(E13,J13,O13) -> 1.4334658
A14: 74.5085 | B14: 0.000782218 | C14: 0.000169344 | D14: =B14/$B$3*100 -> 102.56983 | E14: =C14/$C$3*100 -> 97.026923 | G14: 0.000815758 | H14: 0.000163866 | I14: =G14/$G$3*100 -> 101.86572 | J14: =H14/$H$3*100 -> 93.677862 | Q14: =AVERAGE(B14,G14,L14) -> 0.000798988 | R14: =AVERAGE(C14,H14,M14) -> 0.000166605 | T14: =AVERAGE(D14,I14,N14) -> 102.21777 | U14: =AVERAGE(E14,J14,O14) -> 95.352393 | W14: =_xlfn.STDEV.P(D14,I14,N14) -> 0.35205272 | X14: =_xlfn.STDEV.P(E14,J14,O14) -> 1.6745307
... A109: 692.494 | B109: 0.000769788 | C109: 0.000178157 | D109: =B109/$B$3*100 -> 100.93992 | E109: =C109/$C$3*100 -> 102.0764 | G109: 0.000772996 | H109: 0.000186796 | I109: =G109/$G$3*100 -> 96.525923 | J109: =H109/$H$3*100 -> 106.78634 | Q109: =AVERAGE(B109,G109,L109) -> 0.000771392 | R109: =AVERAGE(C109,H109,M109) -> 0.0001824765 | T109: =AVERAGE(D109,I109,N109) -> 98.73292 | U109: =AVERAGE(E109,J109,O109) -> 104.43137 | W109: =_xlfn.STDEV.P(D109,I109,N109) -> 2.2069974 | X109: =_xlfn.STDEV.P(E109,J109,O109) -> 2.3549694

Sheet 1234 P- 72 hpi
A1: Time | B1: Storage modulus | C1: Loss modulus | D1: Percent storage modulus | E1: Percent loss modulus | G1: Storage modulus | H1: Loss modulus | I1: Percent storage modulus | J1: Percent loss modulus | L1: Storage modulus | M1: Loss modulus | N1: Percent storage modulus | O1: Percent loss modulus | Q1: Average storage modulus | R1: Average loss modulus | T1: Average storage modulus/initial | U1: Average loss modulus/initial | W1: SD G' | X1: SD G''
A2: s | B2: MPa | C2: MPa | D2: MPa | E2: MPa | G2: MPa | H2: MPa | I2: MPa | J2: MPa | L2: MPa | M2: MPa | N2: MPa | O2: MPa | Q2: MPa | R2: MPa | T2: MPa | U2: MPa | W2: MPa | X2: MPa
A3: 6.27187 | B3: 0.00120768 | C3: 0.00014498 | D3: =B3/$B$3*100 -> 100 | E3: =C3/$C$3*100 -> 100 | G3: 0.000820215 | H3: 0.000121001 | I3: =G3/$G$3*100 -> 100 | J3: =H3/$H$3*100 -> 100 | L3: 0.00091907 | M3: 0.000127374 | N3: =L3/$L$3*100 -> 100 | O3: =M3/$M$3*100 -> 100 | Q3: =AVERAGE(B3,G3,L3) -> 0.00098232167 | R3: =AVERAGE(C3,H3,M3) -> 0.00013111833 | T3: =AVERAGE(D3,I3,N3) -> 100 | U3: =AVERAGE(E3,J3,O3) -> 100 | W3: =_xlfn.STDEV.P(D3,I3,N3) -> 0 | X3: =_xlfn.STDEV.P(E3,J3,O3) -> 0
A4: 12.4371 | B4: 0.0012099 | C4: 0.000142167 | D4: =B4/$B$3*100 -> 100.18382 | E4: =C4/$C$3*100 -> 98.059732 | G4: 0.000822959 | H4: 0.000121766 | I4: =G4/$G$3*100 -> 100.33455 | J4: =H4/$H$3*100 -> 100.63223 | L4: 0.000925764 | M4: 0.000124293 | N4: =L4/$L$3*100 -> 100.72834 | O4: =M4/$M$3*100 -> 97.581139 | Q4: =AVERAGE(B4,G4,L4) -> 0.00098620767 | R4: =AVERAGE(C4,H4,M4) -> 0.00012940867 | T4: =AVERAGE(D4,I4,N4) -> 100.41557 | U4: =AVERAGE(E4,J4,O4) -> 98.757699 | W4: =_xlfn.STDEV.P(D4,I4,N4) -> 0.22956438 | X4: =_xlfn.STDEV.P(E4,J4,O4) -> 1.3398138
A5: 18.5455 | B5: 0.00121033 | C5: 0.000140842 | D5: =B5/$B$3*100 -> 100.21943 | E5: =C5/$C$3*100 -> 97.145813 | G5: 0.00082566 | H5: 0.000118887 | I5: =G5/$G$3*100 -> 100.66385 | J5: =H5/$H$3*100 -> 98.252907 | L5: 0.000927273 | M5: 0.000126542 | N5: =L5/$L$3*100 -> 100.89253 | O5: =M5/$M$3*100 -> 99.346805 | Q5: =AVERAGE(B5,G5,L5) -> 0.00098775433 | R5: =AVERAGE(C5,H5,M5) -> 0.000128757 | T5: =AVERAGE(D5,I5,N5) -> 100.59194 | U5: =AVERAGE(E5,J5,O5) -> 98.248509 | W5: =_xlfn.STDEV.P(D5,I5,N5) -> 0.2794587 | X5: =_xlfn.STDEV.P(E5,J5,O5) -> 0.89855671
A6: 24.7914 | B6: 0.00121248 | C6: 0.000141066 | D6: =B6/$B$3*100 -> 100.39746 | E6: =C6/$C$3*100 -> 97.300317 | G6: 0.000826792 | H6: 0.000123709 | I6: =G6/$G$3*100 -> 100.80186 | J6: =H6/$H$3*100 -> 102.238 | L6: 0.000934193 | M6: 0.000129029 | N6: =L6/$L$3*100 -> 101.64547 | O6: =M6/$M$3*100 -> 101.29932 | Q6: =AVERAGE(B6,G6,L6) -> 0.000991155 | R6: =AVERAGE(C6,H6,M6) -> 0.000131268 | T6: =AVERAGE(D6,I6,N6) -> 100.94826 | U6: =AVERAGE(E6,J6,O6) -> 100.27921 | W6: =_xlfn.STDEV.P(D6,I6,N6) -> 0.51990878 | X6: =_xlfn.STDEV.P(E6,J6,O6) -> 2.140972
A7: 31.107 | B7: 0.00121284 | C7: 0.000138626 | D7: =B7/$B$3*100 -> 100.42727 | E7: =C7/$C$3*100 -> 95.617327 | G7: 0.000828432 | H7: 0.000121986 | I7: =G7/$G$3*100 -> 101.00181 | J7: =H7/$H$3*100 -> 100.81404 | L7: 0.000938794 | M7: 0.000128988 | N7: =L7/$L$3*100 -> 102.14608 | O7: =M7/$M$3*100 -> 101.26713 | Q7: =AVERAGE(B7,G7,L7) -> 0.00099335533 | R7: =AVERAGE(C7,H7,M7) -> 0.00012986667 | T7: =AVERAGE(D7,I7,N7) -> 101.19172 | U7: =AVERAGE(E7,J7,O7) -> 99.232835 | W7: =_xlfn.STDEV.P(D7,I7,N7) -> 0.71443777 | X7: =_xlfn.STDEV.P(E7,J7,O7) -> 2.5632333
A8: 37.1924 | B8: 0.00121392 | C8: 0.000138077 | D8: =B8/$B$3*100 -> 100.51669 | E8: =C8/$C$3*100 -> 95.238654 | G8: 0.000830205 | H8: 0.000123373 | I8: =G8/$G$3*100 -> 101.21797 | J8: =H8/$H$3*100 -> 101.96031 | L8: 0.000942309 | M8: 0.000129977 | N8: =L8/$L$3*100 -> 102.52853 | O8: =M8/$M$3*100 -> 102.04359 | Q8: =AVERAGE(B8,G8,L8) -> 0.000995478 | R8: =AVERAGE(C8,H8,M8) -> 0.00013047567 | T8: =AVERAGE(D8,I8,N8) -> 101.42107 | U8: =AVERAGE(E8,J8,O8) -> 99.747519 | W8: =_xlfn.STDEV.P(D8,I8,N8) -> 0.83379111 | X8: =_xlfn.STDEV.P(E8,J8,O8) -> 3.1884303
A9: 43.5262 | B9: 0.00121313 | C9: 0.000137896 | D9: =B9/$B$3*100 -> 100.45128 | E9: =C9/$C$3*100 -> 95.113809 | G9: 0.00083104 | H9: 0.000120872 | I9: =G9/$G$3*100 -> 101.31978 | J9: =H9/$H$3*100 -> 99.893389 | L9: 0.000949023 | M9: 0.000127457 | N9: =L9/$L$3*100 -> 103.25906 | O9: =M9/$M$3*100 -> 100.06516 | Q9: =AVERAGE(B9,G9,L9) -> 0.000997731 | R9: =AVERAGE(C9,H9,M9) -> 0.00012874167 | T9: =AVERAGE(D9,I9,N9) -> 101.6767 | U9: =AVERAGE(E9,J9,O9) -> 98.357454 | W9: =_xlfn.STDEV.P(D9,I9,N9) -> 1.1737264 | X9: =_xlfn.STDEV.P(E9,J9,O9) -> 2.294675
A10: 49.6883 | B10: 0.00121538 | C10: 0.000138998 | D10: =B10/$B$3*100 -> 100.63759 | E10: =C10/$C$3*100 -> 95.873914 | G10: 0.000832934 | H10: 0.000122731 | I10: =G10/$G$3*100 -> 101.55069 | J10: =H10/$H$3*100 -> 101.42974 | L10: 0.000952678 | M10: 0.000129937 | N10: =L10/$L$3*100 -> 103.65674 | O10: =M10/$M$3*100 -> 102.01218 | Q10: =AVERAGE(B10,G10,L10) -> 0.0010003307 | R10: =AVERAGE(C10,H10,M10) -> 0.00013055533 | T10: =AVERAGE(D10,I10,N10) -> 101.94834 | U10: =AVERAGE(E10,J10,O10) -> 99.771946 | W10: =_xlfn.STDEV.P(D10,I10,N10) -> 1.2642298 | X10: =_xlfn.STDEV.P(E10,J10,O10) -> 2.7665627
A11: 55.8005 | B11: 0.00121503 | C11: 0.00013835 | D11: =B11/$B$3*100 -> 100.6086 | E11: =C11/$C$3*100 -> 95.426955 | G11: 0.000833456 | H11: 0.000122902 | I11: =G11/$G$3*100 -> 101.61433 | J11: =H11/$H$3*100 -> 101.57106 | L11: 0.000955225 | M11: 0.000131219 | N11: =L11/$L$3*100 -> 103.93387 | O11: =M11/$M$3*100 -> 103.01867 | Q11: =AVERAGE(B11,G11,L11) -> 0.001001237 | R11: =AVERAGE(C11,H11,M11) -> 0.00013082367 | T11: =AVERAGE(D11,I11,N11) -> 102.05227 | U11: =AVERAGE(E11,J11,O11) -> 100.00556 | W11: =_xlfn.STDEV.P(D11,I11,N11) -> 1.3924042 | X11: =_xlfn.STDEV.P(E11,J11,O11) -> 3.2910608
A12: 62.1114 | B12: 0.00121534 | C12: 0.000136738 | D12: =B12/$B$3*100 -> 100.63427 | E12: =C12/$C$3*100 -> 94.315078 | G12: 0.00083554 | H12: 0.000123608 | I12: =G12/$G$3*100 -> 101.86841 | J12: =H12/$H$3*100 -> 102.15453 | L12: 0.000960627 | M12: 0.000131328 | N12: =L12/$L$3*100 -> 104.52164 | O12: =M12/$M$3*100 -> 103.10424 | Q12: =AVERAGE(B12,G12,L12) -> 0.0010038357 | R12: =AVERAGE(C12,H12,M12) -> 0.000130558 | T12: =AVERAGE(D12,I12,N12) -> 102.34144 | U12: =AVERAGE(E12,J12,O12) -> 99.85795 | W12: =_xlfn.STDEV.P(D12,I12,N12) -> 1.621874 | X12: =_xlfn.STDEV.P(E12,J12,O12) -> 3.938533
A13: 68.3388 | B13: 0.00121518 | C13: 0.000136379 | D13: =B13/$B$3*100 -> 100.62103 | E13: =C13/$C$3*100 -> 94.067458 | G13: 0.000836275 | H13: 0.000122552 | I13: =G13/$G$3*100 -> 101.95802 | J13: =H13/$H$3*100 -> 101.28181 | L13: 0.000965956 | M13: 0.000135038 | N13: =L13/$L$3*100 -> 105.10146 | O13: =M13/$M$3*100 -> 106.01693 | Q13: =AVERAGE(B13,G13,L13) -> 0.0010058037 | R13: =AVERAGE(C13,H13,M13) -> 0.000131323 | T13: =AVERAGE(D13,I13,N13) -> 102.56017 | U13: =AVERAGE(E13,J13,O13) -> 100.4554 | W13: =_xlfn.STDEV.P(D13,I13,N13) -> 1.878033 | X13: =_xlfn.STDEV.P(E13,J13,O13) -> 4.9132248
A14: 74.5085 | B14: 0.00121565 | C14: 0.000135871 | D14: =B14/$B$3*100 -> 100.65994 | E14: =C14/$C$3*100 -> 93.717064 | G14: 0.000838954 | H14: 0.000123747 | I14: =G14/$G$3*100 -> 102.28464 | J14: =H14/$H$3*100 -> 102.2694 | L14: 0.000969628 | M14: 0.000132986 | N14: =L14/$L$3*100 -> 105.501 | O14: =M14/$M$3*100 -> 104.40592 | Q14: =AVERAGE(B14,G14,L14) -> 0.0010080773 | R14: =AVERAGE(C14,H14,M14) -> 0.000130868 | T14: =AVERAGE(D14,I14,N14) -> 102.81519 | U14: =AVERAGE(E14,J14,O14) -> 100.1308 | W14: =_xlfn.STDEV.P(D14,I14,N14) -> 2.0116427 | X14: =_xlfn.STDEV.P(E14,J14,O14) -> 4.6183078
... A109: 692.494 | B109: 0.000720869 | C109: 0.000113392 | D109: =B109/$B$3*100 -> 59.690398 | E109: =C109/$C$3*100 -> 78.212167 | G109: 0.000559541 | H109: 0.000156232 | I109: =G109/$G$3*100 -> 68.218821 | J109: =H109/$H$3*100 -> 129.11629 | L109: 0.000586707 | M109: 0.000108164 | N109: =L109/$L$3*100 -> 63.837031 | O109: =M109/$M$3*100 -> 84.918429 | Q109: =AVERAGE(B109,G109,L109) -> 0.00062237233 | R109: =AVERAGE(C109,H109,M109) -> 0.00012592933 | T109: =AVERAGE(D109,I109,N109) -> 63.915417 | U109: =AVERAGE(E109,J109,O109) -> 97.415628 | W109: =_xlfn.STDEV.P(D109,I109,N109) -> 3.4821551 | X109: =_xlfn.STDEV.P(E109,J109,O109) -> 22.582329

Sheet 1234 P+ 72 hpi
A1: Time | B1: Storage modulus | C1: Loss modulus | D1: Percent storage modulus | E1: Percent loss modulus | G1: Storage modulus | H1: Loss modulus | I1: Percent storage modulus | J1: Percent loss modulus | L1: Storage modulus | M1: Loss modulus | N1: Percent storage modulus | O1: Percent loss modulus | Q1: Average storage modulus | R1: Average loss modulus | T1: Average storage modulus/initial | U1: Average loss modulus/initial | W1: SD G' | X1: SD G''
A2: s | B2: MPa | C2: MPa | D2: MPa | E2: MPa | G2: MPa | H2: MPa | I2: MPa | J2: MPa | L2: MPa | M2: MPa | N2: MPa | O2: MPa | Q2: MPa | R2: MPa | T2: MPa | U2: MPa | W2: MPa | X2: MPa
A3: 6.27187 | B3: 0.00127728 | C3: 0.00015087 | D3: =B3/$B$3*100 -> 100 | E3: =C3/$C$3*100 -> 100 | G3: 0.000754693 | H3: 0.000122515 | I3: =G3/$G$3*100 -> 100 | J3: =H3/$H$3*100 -> 100 | Q3: =AVERAGE(B3,G3,L3) -> 0.0010159865 | R3: =AVERAGE(C3,H3,M3) -> 0.0001366925 | T3: =AVERAGE(D3,I3,N3) -> 100 | U3: =AVERAGE(E3,J3,O3) -> 100 | W3: =_xlfn.STDEV.P(D3,I3,N3) -> 0 | X3: =_xlfn.STDEV.P(E3,J3,O3) -> 0
A4: 12.4371 | B4: 0.00127875 | C4: 0.000148995 | D4: =B4/$B$3*100 -> 100.11509 | E4: =C4/$C$3*100 -> 98.757208 | G4: 0.000756783 | H4: 0.00012429 | I4: =G4/$G$3*100 -> 100.27693 | J4: =H4/$H$3*100 -> 101.4488 | Q4: =AVERAGE(B4,G4,L4) -> 0.0010177665 | R4: =AVERAGE(C4,H4,M4) -> 0.0001366425 | T4: =AVERAGE(D4,I4,N4) -> 100.19601 | U4: =AVERAGE(E4,J4,O4) -> 100.10301 | W4: =_xlfn.STDEV.P(D4,I4,N4) -> 0.080922743 | X4: =_xlfn.STDEV.P(E4,J4,O4) -> 1.345797
A5: 18.5455 | B5: 0.00128148 | C5: 0.000148435 | D5: =B5/$B$3*100 -> 100.32882 | E5: =C5/$C$3*100 -> 98.386028 | G5: 0.000755727 | H5: 0.000121422 | I5: =G5/$G$3*100 -> 100.13701 | J5: =H5/$H$3*100 -> 99.107864 | Q5: =AVERAGE(B5,G5,L5) -> 0.0010186035 | R5: =AVERAGE(C5,H5,M5) -> 0.0001349285 | T5: =AVERAGE(D5,I5,N5) -> 100.23292 | U5: =AVERAGE(E5,J5,O5) -> 98.746946 | W5: =_xlfn.STDEV.P(D5,I5,N5) -> 0.095907198 | X5: =_xlfn.STDEV.P(E5,J5,O5) -> 0.36091832
A6: 24.7914 | B6: 0.00128244 | C6: 0.000151044 | D6: =B6/$B$3*100 -> 100.40398 | E6: =C6/$C$3*100 -> 100.11533 | G6: 0.000757899 | H6: 0.000122226 | I6: =G6/$G$3*100 -> 100.42481 | J6: =H6/$H$3*100 -> 99.764111 | Q6: =AVERAGE(B6,G6,L6) -> 0.0010201695 | R6: =AVERAGE(C6,H6,M6) -> 0.000136635 | T6: =AVERAGE(D6,I6,N6) -> 100.4144 | U6: =AVERAGE(E6,J6,O6) -> 99.939721 | W6: =_xlfn.STDEV.P(D6,I6,N6) -> 0.010412517 | X6: =_xlfn.STDEV.P(E6,J6,O6) -> 0.17561028
A7: 31.107 | B7: 0.00128346 | C7: 0.000147415 | D7: =B7/$B$3*100 -> 100.48384 | E7: =C7/$C$3*100 -> 97.709949 | G7: 0.000759658 | H7: 0.000120776 | I7: =G7/$G$3*100 -> 100.65788 | J7: =H7/$H$3*100 -> 98.580582 | Q7: =AVERAGE(B7,G7,L7) -> 0.001021559 | R7: =AVERAGE(C7,H7,M7) -> 0.0001340955 | T7: =AVERAGE(D7,I7,N7) -> 100.57086 | U7: =AVERAGE(E7,J7,O7) -> 98.145265 | W7: =_xlfn.STDEV.P(D7,I7,N7) -> 0.087021371 | X7: =_xlfn.STDEV.P(E7,J7,O7) -> 0.4353165
A8: 37.1924 | B8: 0.00128475 | C8: 0.000153574 | D8: =B8/$B$3*100 -> 100.58484 | E8: =C8/$C$3*100 -> 101.79227 | G8: 0.000759718 | H8: 0.000123713 | I8: =G8/$G$3*100 -> 100.66583 | J8: =H8/$H$3*100 -> 100.97784 | Q8: =AVERAGE(B8,G8,L8) -> 0.001022234 | R8: =AVERAGE(C8,H8,M8) -> 0.0001386435 | T8: =AVERAGE(D8,I8,N8) -> 100.62534 | U8: =AVERAGE(E8,J8,O8) -> 101.38506 | W8: =_xlfn.STDEV.P(D8,I8,N8) -> 0.040498565 | X8: =_xlfn.STDEV.P(E8,J8,O8) -> 0.40721602
A9: 43.5262 | B9: 0.00128686 | C9: 0.00015837 | D9: =B9/$B$3*100 -> 100.75003 | E9: =C9/$C$3*100 -> 104.97117 | G9: 0.000761035 | H9: 0.000125029 | I9: =G9/$G$3*100 -> 100.84034 | J9: =H9/$H$3*100 -> 102.05199 | Q9: =AVERAGE(B9,G9,L9) -> 0.0010239475 | R9: =AVERAGE(C9,H9,M9) -> 0.0001416995 | T9: =AVERAGE(D9,I9,N9) -> 100.79519 | U9: =AVERAGE(E9,J9,O9) -> 103.51158 | W9: =_xlfn.STDEV.P(D9,I9,N9) -> 0.045155193 | X9: =_xlfn.STDEV.P(E9,J9,O9) -> 1.4595868
A10: 49.6883 | B10: 0.00128821 | C10: 0.000158253 | D10: =B10/$B$3*100 -> 100.85572 | E10: =C10/$C$3*100 -> 104.89362 | G10: 0.000762373 | H10: 0.000123485 | I10: =G10/$G$3*100 -> 101.01763 | J10: =H10/$H$3*100 -> 100.79174 | Q10: =AVERAGE(B10,G10,L10) -> 0.0010252915 | R10: =AVERAGE(C10,H10,M10) -> 0.000140869 | T10: =AVERAGE(D10,I10,N10) -> 100.93668 | U10: =AVERAGE(E10,J10,O10) -> 102.84268 | W10: =_xlfn.STDEV.P(D10,I10,N10) -> 0.080953835 | X10: =_xlfn.STDEV.P(E10,J10,O10) -> 2.0509386
A11: 55.8005 | B11: 0.00128767 | C11: 0.000156955 | D11: =B11/$B$3*100 -> 100.81345 | E11: =C11/$C$3*100 -> 104.03327 | G11: 0.000764531 | H11: 0.000120158 | I11: =G11/$G$3*100 -> 101.30358 | J11: =H11/$H$3*100 -> 98.076154 | Q11: =AVERAGE(B11,G11,L11) -> 0.0010261005 | R11: =AVERAGE(C11,H11,M11) -> 0.0001385565 | T11: =AVERAGE(D11,I11,N11) -> 101.05851 | U11: =AVERAGE(E11,J11,O11) -> 101.05471 | W11: =_xlfn.STDEV.P(D11,I11,N11) -> 0.24506455 | X11: =_xlfn.STDEV.P(E11,J11,O11) -> 2.9785599
A12: 62.1114 | B12: 0.00129113 | C12: 0.000157467 | D12: =B12/$B$3*100 -> 101.08434 | E12: =C12/$C$3*100 -> 104.37264 | G12: 0.000764493 | H12: 0.00012314 | I12: =G12/$G$3*100 -> 101.29854 | J12: =H12/$H$3*100 -> 100.51014 | Q12: =AVERAGE(B12,G12,L12) -> 0.0010278115 | R12: =AVERAGE(C12,H12,M12) -> 0.0001403035 | T12: =AVERAGE(D12,I12,N12) -> 101.19144 | U12: =AVERAGE(E12,J12,O12) -> 102.44139 | W12: =_xlfn.STDEV.P(D12,I12,N12) -> 0.1071029 | X12: =_xlfn.STDEV.P(E12,J12,O12) -> 1.9312485
A13: 68.3388 | B13: 0.00129014 | C13: 0.00015684 | D13: =B13/$B$3*100 -> 101.00683 | E13: =C13/$C$3*100 -> 103.95705 | G13: 0.000763708 | H13: 0.000122537 | I13: =G13/$G$3*100 -> 101.19453 | J13: =H13/$H$3*100 -> 100.01796 | Q13: =AVERAGE(B13,G13,L13) -> 0.001026924 | R13: =AVERAGE(C13,H13,M13) -> 0.0001396885 | T13: =AVERAGE(D13,I13,N13) -> 101.10068 | U13: =AVERAGE(E13,J13,O13) -> 101.9875 | W13: =_xlfn.STDEV.P(D13,I13,N13) -> 0.093849224 | X13: =_xlfn.STDEV.P(E13,J13,O13) -> 1.9695461
A14: 74.5085 | B14: 0.00129125 | C14: 0.000158409 | D14: =B14/$B$3*100 -> 101.09373 | E14: =C14/$C$3*100 -> 104.99702 | G14: 0.000766994 | H14: 0.000124622 | I14: =G14/$G$3*100 -> 101.62993 | J14: =H14/$H$3*100 -> 101.71979 | Q14: =AVERAGE(B14,G14,L14) -> 0.001029122 | R14: =AVERAGE(C14,H14,M14) -> 0.0001415155 | T14: =AVERAGE(D14,I14,N14) -> 101.36183 | U14: =AVERAGE(E14,J14,O14) -> 103.3584 | W14: =_xlfn.STDEV.P(D14,I14,N14) -> 0.26810193 | X14: =_xlfn.STDEV.P(E14,J14,O14) -> 1.6386139
... A109: 692.494 | B109: 0.000828005 | C109: 0.000104357 | D109: =B109/$B$3*100 -> 64.825645 | E109: =C109/$C$3*100 -> 69.170146 | G109: 0.00051896 | H109: 0.000128853 | I109: =G109/$G$3*100 -> 68.764385 | J109: =H109/$H$3*100 -> 105.17324 | Q109: =AVERAGE(B109,G109,L109) -> 0.0006734825 | R109: =AVERAGE(C109,H109,M109) -> 0.000116605 | T109: =AVERAGE(D109,I109,N109) -> 66.795015 | U109: =AVERAGE(E109,J109,O109) -> 87.171695 | W109: =_xlfn.STDEV.P(D109,I109,N109) -> 1.9693699 | X109: =_xlfn.STDEV.P(E109,J109,O109) -> 18.001549

Sheet 1250 P- 72 hpi
A1: Time | B1: Storage modulus | C1: Loss modulus | D1: Percent storage modulus | E1: Percent loss modulus | G1: Storage modulus | H1: Loss modulus | I1: Percent storage modulus | J1: Percent loss modulus | L1: Storage modulus | M1: Loss modulus | N1: Percent storage modulus | O1: Percent loss modulus | Q1: Average storage modulus | R1: Average loss modulus | T1: Average storage modulus/initial | U1: Average loss modulus/initial | W1: SD G' | X1: SD G''
A2: s | B2: MPa | C2: MPa | D2: MPa | E2: MPa | G2: MPa | H2: MPa | I2: MPa | J2: MPa | L2: MPa | M2: MPa | N2: MPa | O2: MPa | Q2: MPa | R2: MPa | T2: MPa | U2: MPa | W2: MPa | X2: MPa
A3: 6.27187 | B3: 0.00083851 | C3: 0.000183128 | D3: =B3/$B$3*100 -> 100 | E3: =C3/$C$3*100 -> 100 | G3: 0.000799428 | H3: 0.000178792 | I3: =G3/$G$3*100 -> 100 | J3: =H3/$H$3*100 -> 100 | L3: 0.00097525 | M3: 0.000183326 | N3: =L3/$L$3*100 -> 100 | O3: =M3/$M$3*100 -> 100 | Q3: =AVERAGE(B3,G3,L3) -> 0.00087106267 | R3: =AVERAGE(C3,H3,M3) -> 0.00018174867 | T3: =AVERAGE(D3,I3,N3) -> 100 | U3: =AVERAGE(E3,J3,O3) -> 100 | W3: =_xlfn.STDEV.P(D3,I3,N3) -> 0 | X3: =_xlfn.STDEV.P(E3,J3,O3) -> 0
A4: 12.4371 | B4: 0.000842037 | C4: 0.000184364 | D4: =B4/$B$3*100 -> 100.42063 | E4: =C4/$C$3*100 -> 100.67494 | G4: 0.000802331 | H4: 0.00017965 | I4: =G4/$G$3*100 -> 100.36313 | J4: =H4/$H$3*100 -> 100.47989 | L4: 0.000978854 | M4: 0.000185789 | N4: =L4/$L$3*100 -> 100.36955 | O4: =M4/$M$3*100 -> 101.34351 | Q4: =AVERAGE(B4,G4,L4) -> 0.00087440733 | R4: =AVERAGE(C4,H4,M4) -> 0.00018326767 | T4: =AVERAGE(D4,I4,N4) -> 100.38444 | U4: =AVERAGE(E4,J4,O4) -> 100.83278 | W4: =_xlfn.STDEV.P(D4,I4,N4) -> 0.02572447 | X4: =_xlfn.STDEV.P(E4,J4,O4) -> 0.36981565
A5: 18.5455 | B5: 0.000845861 | C5: 0.000183624 | D5: =B5/$B$3*100 -> 100.87667 | E5: =C5/$C$3*100 -> 100.27085 | G5: 0.000806079 | H5: 0.000180075 | I5: =G5/$G$3*100 -> 100.83197 | J5: =H5/$H$3*100 -> 100.71759 | L5: 0.000982026 | M5: 0.000191075 | N5: =L5/$L$3*100 -> 100.6948 | O5: =M5/$M$3*100 -> 104.2269 | Q5: =AVERAGE(B5,G5,L5) -> 0.00087798867 | R5: =AVERAGE(C5,H5,M5) -> 0.00018492467 | T5: =AVERAGE(D5,I5,N5) -> 100.80115 | U5: =AVERAGE(E5,J5,O5) -> 101.73845 | W5: =_xlfn.STDEV.P(D5,I5,N5) -> 0.07738407 | X5: =_xlfn.STDEV.P(E5,J5,O5) -> 1.7690267
A6: 24.7914 | B6: 0.000849108 | C6: 0.000187725 | D6: =B6/$B$3*100 -> 101.26391 | E6: =C6/$C$3*100 -> 102.51027 | G6: 0.000810809 | H6: 0.000183369 | I6: =G6/$G$3*100 -> 101.42364 | J6: =H6/$H$3*100 -> 102.55996 | L6: 0.000984422 | M6: 0.000186566 | N6: =L6/$L$3*100 -> 100.94048 | O6: =M6/$M$3*100 -> 101.76734 | Q6: =AVERAGE(B6,G6,L6) -> 0.00088144633 | R6: =AVERAGE(C6,H6,M6) -> 0.00018588667 | T6: =AVERAGE(D6,I6,N6) -> 101.20934 | U6: =AVERAGE(E6,J6,O6) -> 102.27919 | W6: =_xlfn.STDEV.P(D6,I6,N6) -> 0.20098996 | X6: =_xlfn.STDEV.P(E6,J6,O6) -> 0.36249768
A7: 31.107 | B7: 0.000848774 | C7: 0.000183926 | D7: =B7/$B$3*100 -> 101.22408 | E7: =C7/$C$3*100 -> 100.43576 | G7: 0.000813789 | H7: 0.000185764 | I7: =G7/$G$3*100 -> 101.79641 | J7: =H7/$H$3*100 -> 103.8995 | L7: 0.000986355 | M7: 0.000181296 | N7: =L7/$L$3*100 -> 101.13868 | O7: =M7/$M$3*100 -> 98.892683 | Q7: =AVERAGE(B7,G7,L7) -> 0.00088297267 | R7: =AVERAGE(C7,H7,M7) -> 0.000183662 | T7: =AVERAGE(D7,I7,N7) -> 101.38639 | U7: =AVERAGE(E7,J7,O7) -> 101.07598 | W7: =_xlfn.STDEV.P(D7,I7,N7) -> 0.29201645 | X7: =_xlfn.STDEV.P(E7,J7,O7) -> 2.0935576
A8: 37.1924 | B8: 0.000851195 | C8: 0.000180113 | D8: =B8/$B$3*100 -> 101.5128 | E8: =C8/$C$3*100 -> 98.353611 | G8: 0.000815187 | H8: 0.000184808 | I8: =G8/$G$3*100 -> 101.97128 | J8: =H8/$H$3*100 -> 103.3648 | L8: 0.000991113 | M8: 0.000186384 | N8: =L8/$L$3*100 -> 101.62656 | O8: =M8/$M$3*100 -> 101.66807 | Q8: =AVERAGE(B8,G8,L8) -> 0.00088583167 | R8: =AVERAGE(C8,H8,M8) -> 0.00018376833 | T8: =AVERAGE(D8,I8,N8) -> 101.70355 | U8: =AVERAGE(E8,J8,O8) -> 101.12883 | W8: =_xlfn.STDEV.P(D8,I8,N8) -> 0.19493096 | X8: =_xlfn.STDEV.P(E8,J8,O8) -> 2.0810412
A9: 43.5262 | B9: 0.000854881 | C9: 0.000188454 | D9: =B9/$B$3*100 -> 101.95239 | E9: =C9/$C$3*100 -> 102.90835 | G9: 0.000816853 | H9: 0.000183181 | I9: =G9/$G$3*100 -> 102.17968 | J9: =H9/$H$3*100 -> 102.45481 | L9: 0.000994151 | M9: 0.000186756 | N9: =L9/$L$3*100 -> 101.93807 | O9: =M9/$M$3*100 -> 101.87098 | Q9: =AVERAGE(B9,G9,L9) -> 0.00088862833 | R9: =AVERAGE(C9,H9,M9) -> 0.00018613033 | T9: =AVERAGE(D9,I9,N9) -> 102.02338 | U9: =AVERAGE(E9,J9,O9) -> 102.41138 | W9: =_xlfn.STDEV.P(D9,I9,N9) -> 0.11067729 | X9: =_xlfn.STDEV.P(E9,J9,O9) -> 0.42461408
A10: 49.6883 | B10: 0.000862302 | C10: 0.000196145 | D10: =B10/$B$3*100 -> 102.83741 | E10: =C10/$C$3*100 -> 107.10814 | G10: 0.000818398 | H10: 0.000183389 | I10: =G10/$G$3*100 -> 102.37295 | J10: =H10/$H$3*100 -> 102.57114 | L10: 0.000996439 | M10: 0.000187035 | N10: =L10/$L$3*100 -> 102.17267 | O10: =M10/$M$3*100 -> 102.02317 | Q10: =AVERAGE(B10,G10,L10) -> 0.00089237967 | R10: =AVERAGE(C10,H10,M10) -> 0.00018885633 | T10: =AVERAGE(D10,I10,N10) -> 102.46101 | U10: =AVERAGE(E10,J10,O10) -> 103.90082 | W10: =_xlfn.STDEV.P(D10,I10,N10) -> 0.27843189 | X10: =_xlfn.STDEV.P(E10,J10,O10) -> 2.2789267
A11: 55.8005 | B11: 0.000862444 | C11: 0.000191202 | D11: =B11/$B$3*100 -> 102.85435 | E11: =C11/$C$3*100 -> 104.40894 | G11: 0.000821557 | H11: 0.000183463 | I11: =G11/$G$3*100 -> 102.7681 | J11: =H11/$H$3*100 -> 102.61253 | L11: 0.000997758 | M11: 0.000189592 | N11: =L11/$L$3*100 -> 102.30792 | O11: =M11/$M$3*100 -> 103.41795 | Q11: =AVERAGE(B11,G11,L11) -> 0.00089391967 | R11: =AVERAGE(C11,H11,M11) -> 0.00018808567 | T11: =AVERAGE(D11,I11,N11) -> 102.64346 | U11: =AVERAGE(E11,J11,O11) -> 103.47981 | W11: =_xlfn.STDEV.P(D11,I11,N11) -> 0.23985874 | X11: =_xlfn.STDEV.P(E11,J11,O11) -> 0.73468231
A12: 62.1114 | B12: 0.000867776 | C12: 0.000201138 | D12: =B12/$B$3*100 -> 103.49024 | E12: =C12/$C$3*100 -> 109.83465 | G12: 0.000825929 | H12: 0.000189079 | I12: =G12/$G$3*100 -> 103.315 | J12: =H12/$H$3*100 -> 105.75361 | L12: 0.00100232 | M12: 0.000189055 | N12: =L12/$L$3*100 -> 102.7757 | O12: =M12/$M$3*100 -> 103.12503 | Q12: =AVERAGE(B12,G12,L12) -> 0.000898675 | R12: =AVERAGE(C12,H12,M12) -> 0.00019309067 | T12: =AVERAGE(D12,I12,N12) -> 103.19364 | U12: =AVERAGE(E12,J12,O12) -> 106.23777 | W12: =_xlfn.STDEV.P(D12,I12,N12) -> 0.30406847 | X12: =_xlfn.STDEV.P(E12,J12,O12) -> 2.7605004
A13: 68.3388 | B13: 0.000870805 | C13: 0.000202079 | D13: =B13/$B$3*100 -> 103.85147 | E13: =C13/$C$3*100 -> 110.3485 | G13: 0.000828865 | H13: 0.000188648 | I13: =G13/$G$3*100 -> 103.68226 | J13: =H13/$H$3*100 -> 105.51255 | L13: 0.00100494 | M13: 0.000192704 | N13: =L13/$L$3*100 -> 103.04435 | O13: =M13/$M$3*100 -> 105.11548 | Q13: =AVERAGE(B13,G13,L13) -> 0.00090153667 | R13: =AVERAGE(C13,H13,M13) -> 0.000194477 | T13: =AVERAGE(D13,I13,N13) -> 103.52603 | U13: =AVERAGE(E13,J13,O13) -> 106.99218 | W13: =_xlfn.STDEV.P(D13,I13,N13) -> 0.34753382 | X13: =_xlfn.STDEV.P(E13,J13,O13) -> 2.3788089
A14: 74.5085 | B14: 0.000872958 | C14: 0.000202292 | D14: =B14/$B$3*100 -> 104.10824 | E14: =C14/$C$3*100 -> 110.46481 | G14: 0.000831017 | H14: 0.000188357 | I14: =G14/$G$3*100 -> 103.95145 | J14: =H14/$H$3*100 -> 105.34979 | L14: 0.00100663 | M14: 0.000195769 | N14: =L14/$L$3*100 -> 103.21764 | O14: =M14/$M$3*100 -> 106.78736 | Q14: =AVERAGE(B14,G14,L14) -> 0.000903535 | R14: =AVERAGE(C14,H14,M14) -> 0.00019547267 | T14: =AVERAGE(D14,I14,N14) -> 103.75911 | U14: =AVERAGE(E14,J14,O14) -> 107.53399 | W14: =_xlfn.STDEV.P(D14,I14,N14) -> 0.38819232 | X14: =_xlfn.STDEV.P(E14,J14,O14) -> 2.1539026
... A109: 692.494 | B109: 0.000821013 | C109: 0.000180164 | D109: =B109/$B$3*100 -> 97.913322 | E109: =C109/$C$3*100 -> 98.38146 | G109: 0.000788558 | H109: 0.000170405 | I109: =G109/$G$3*100 -> 98.640278 | J109: =H109/$H$3*100 -> 95.309074 | L109: 0.000953012 | M109: 0.000195052 | N109: =L109/$L$3*100 -> 97.719764 | O109: =M109/$M$3*100 -> 106.39626 | Q109: =AVERAGE(B109,G109,L109) -> 0.00085419433 | R109: =AVERAGE(C109,H109,M109) -> 0.00018187367 | T109: =AVERAGE(D109,I109,N109) -> 98.091121 | U109: =AVERAGE(E109,J109,O109) -> 100.02893 | W109: =_xlfn.STDEV.P(D109,I109,N109) -> 0.39627071 | X109: =_xlfn.STDEV.P(E109,J109,O109) -> 4.6738291

Sheet 1250 P+ 72 hpi
A1: Time | B1: Storage modulus | C1: Loss modulus | D1: Percent storage modulus | E1: Percent loss modulus | G1: Storage modulus | H1: Loss modulus | I1: Percent storage modulus | J1: Percent loss modulus | L1: Storage modulus | M1: Loss modulus | N1: Percent storage modulus | O1: Percent loss modulus | Q1: Average storage modulus | R1: Average loss modulus | T1: Average storage modulus/initial | U1: Average loss modulus/initial | W1: SD G' | X1: SD G''
A2: s | B2: MPa | C2: MPa | D2: MPa | E2: MPa | G2: MPa | H2: MPa | I2: MPa | J2: MPa | L2: MPa | M2: MPa | N2: MPa | O2: MPa | Q2: MPa | R2: MPa | T2: MPa | U2: MPa | W2: MPa | X2: MPa
A3: 6.27187 | B3: 0.00161088 | C3: 0.000280163 | D3: =B3/$B$3*100 -> 100 | E3: =C3/$C$3*100 -> 100 | G3: 0.0012286 | H3: 0.000249814 | I3: =G3/$G$3*100 -> 100 | J3: =H3/$H$3*100 -> 100 | Q3: =AVERAGE(B3,G3,L3) -> 0.00141974 | R3: =AVERAGE(C3,H3,M3) -> 0.0002649885 | T3: =AVERAGE(D3,I3,N3) -> 100 | U3: =AVERAGE(E3,J3,O3) -> 100 | W3: =_xlfn.STDEV.P(D3,I3,N3) -> 0 | X3: =_xlfn.STDEV.P(E3,J3,O3) -> 0
A4: 12.4371 | B4: 0.00162206 | C4: 0.000285531 | D4: =B4/$B$3*100 -> 100.69403 | E4: =C4/$C$3*100 -> 101.91603 | G4: 0.00123629 | H4: 0.000255088 | I4: =G4/$G$3*100 -> 100.62592 | J4: =H4/$H$3*100 -> 102.11117 | Q4: =AVERAGE(B4,G4,L4) -> 0.001429175 | R4: =AVERAGE(C4,H4,M4) -> 0.0002703095 | T4: =AVERAGE(D4,I4,N4) -> 100.65997 | U4: =AVERAGE(E4,J4,O4) -> 102.0136 | W4: =_xlfn.STDEV.P(D4,I4,N4) -> 0.034057458 | X4: =_xlfn.STDEV.P(E4,J4,O4) -> 0.097571628
A5: 18.5455 | B5: 0.00163064 | C5: 0.000286981 | D5: =B5/$B$3*100 -> 101.22666 | E5: =C5/$C$3*100 -> 102.43358 | G5: 0.00123893 | H5: 0.000254932 | I5: =G5/$G$3*100 -> 100.84079 | J5: =H5/$H$3*100 -> 102.04872 | Q5: =AVERAGE(B5,G5,L5) -> 0.001434785 | R5: =AVERAGE(C5,H5,M5) -> 0.0002709565 | T5: =AVERAGE(D5,I5,N5) -> 101.03373 | U5: =AVERAGE(E5,J5,O5) -> 102.24115 | W5: =_xlfn.STDEV.P(D5,I5,N5) -> 0.19293216 | X5: =_xlfn.STDEV.P(E5,J5,O5) -> 0.19242953
A6: 24.7914 | B6: 0.00163571 | C6: 0.000286251 | D6: =B6/$B$3*100 -> 101.54139 | E6: =C6/$C$3*100 -> 102.17302 | G6: 0.00124708 | H6: 0.000257788 | I6: =G6/$G$3*100 -> 101.50415 | J6: =H6/$H$3*100 -> 103.19197 | Q6: =AVERAGE(B6,G6,L6) -> 0.001441395 | R6: =AVERAGE(C6,H6,M6) -> 0.0002720195 | T6: =AVERAGE(D6,I6,N6) -> 101.52277 | U6: =AVERAGE(E6,J6,O6) -> 102.6825 | W6: =_xlfn.STDEV.P(D6,I6,N6) -> 0.018621229 | X6: =_xlfn.STDEV.P(E6,J6,O6) -> 0.50947706
A7: 31.107 | B7: 0.00164154 | C7: 0.000285753 | D7: =B7/$B$3*100 -> 101.90331 | E7: =C7/$C$3*100 -> 101.99527 | G7: 0.00125183 | H7: 0.000257894 | I7: =G7/$G$3*100 -> 101.89077 | J7: =H7/$H$3*100 -> 103.23441 | Q7: =AVERAGE(B7,G7,L7) -> 0.001446685 | R7: =AVERAGE(C7,H7,M7) -> 0.0002718235 | T7: =AVERAGE(D7,I7,N7) -> 101.89704 | U7: =AVERAGE(E7,J7,O7) -> 102.61484 | W7: =_xlfn.STDEV.P(D7,I7,N7) -> 0.0062687634 | X7: =_xlfn.STDEV.P(E7,J7,O7) -> 0.61956968
A8: 37.1924 | B8: 0.00164701 | C8: 0.000283947 | D8: =B8/$B$3*100 -> 102.24287 | E8: =C8/$C$3*100 -> 101.35064 | G8: 0.00124958 | H8: 0.000251542 | I8: =G8/$G$3*100 -> 101.70763 | J8: =H8/$H$3*100 -> 100.69171 | Q8: =AVERAGE(B8,G8,L8) -> 0.001448295 | R8: =AVERAGE(C8,H8,M8) -> 0.0002677445 | T8: =AVERAGE(D8,I8,N8) -> 101.97525 | U8: =AVERAGE(E8,J8,O8) -> 101.02118 | W8: =_xlfn.STDEV.P(D8,I8,N8) -> 0.26761938 | X8: =_xlfn.STDEV.P(E8,J8,O8) -> 0.32946383
A9: 43.5262 | B9: 0.00165089 | C9: 0.000279363 | D9: =B9/$B$3*100 -> 102.48374 | E9: =C9/$C$3*100 -> 99.714452 | G9: 0.00125565 | H9: 0.000253983 | I9: =G9/$G$3*100 -> 102.20169 | J9: =H9/$H$3*100 -> 101.66884 | Q9: =AVERAGE(B9,G9,L9) -> 0.00145327 | R9: =AVERAGE(C9,H9,M9) -> 0.000266673 | T9: =AVERAGE(D9,I9,N9) -> 102.34271 | U9: =AVERAGE(E9,J9,O9) -> 100.69165 | W9: =_xlfn.STDEV.P(D9,I9,N9) -> 0.14102131 | X9: =_xlfn.STDEV.P(E9,J9,O9) -> 0.97719484
A10: 49.6883 | B10: 0.00165312 | C10: 0.00027891 | D10: =B10/$B$3*100 -> 102.62217 | E10: =C10/$C$3*100 -> 99.55276 | G10: 0.00125691 | H10: 0.000253945 | I10: =G10/$G$3*100 -> 102.30425 | J10: =H10/$H$3*100 -> 101.65363 | Q10: =AVERAGE(B10,G10,L10) -> 0.001455015 | R10: =AVERAGE(C10,H10,M10) -> 0.0002664275 | T10: =AVERAGE(D10,I10,N10) -> 102.46321 | U10: =AVERAGE(E10,J10,O10) -> 100.6032 | W10: =_xlfn.STDEV.P(D10,I10,N10) -> 0.15896026 | X10: =_xlfn.STDEV.P(E10,J10,O10) -> 1.050435
A11: 55.8005 | B11: 0.00165751 | C11: 0.000278337 | D11: =B11/$B$3*100 -> 102.89469 | E11: =C11/$C$3*100 -> 99.348237 | G11: 0.00125915 | H11: 0.00025192 | I11: =G11/$G$3*100 -> 102.48657 | J11: =H11/$H$3*100 -> 100.84303 | Q11: =AVERAGE(B11,G11,L11) -> 0.00145833 | R11: =AVERAGE(C11,H11,M11) -> 0.0002651285 | T11: =AVERAGE(D11,I11,N11) -> 102.69063 | U11: =AVERAGE(E11,J11,O11) -> 100.09563 | W11: =_xlfn.STDEV.P(D11,I11,N11) -> 0.20406051 | X11: =_xlfn.STDEV.P(E11,J11,O11) -> 0.74739532
A12: 62.1114 | B12: 0.00166324 | C12: 0.00027703 | D12: =B12/$B$3*100 -> 103.2504 | E12: =C12/$C$3*100 -> 98.881722 | G12: 0.00126515 | H12: 0.000255699 | I12: =G12/$G$3*100 -> 102.97493 | J12: =H12/$H$3*100 -> 102.35575 | Q12: =AVERAGE(B12,G12,L12) -> 0.001464195 | R12: =AVERAGE(C12,H12,M12) -> 0.0002663645 | T12: =AVERAGE(D12,I12,N12) -> 103.11266 | U12: =AVERAGE(E12,J12,O12) -> 100.61874 | W12: =_xlfn.STDEV.P(D12,I12,N12) -> 0.13773324 | X12: =_xlfn.STDEV.P(E12,J12,O12) -> 1.7370151
A13: 68.3388 | B13: 0.00166568 | C13: 0.000276885 | D13: =B13/$B$3*100 -> 103.40187 | E13: =C13/$C$3*100 -> 98.829967 | G13: 0.00126591 | H13: 0.000250962 | I13: =G13/$G$3*100 -> 103.03679 | J13: =H13/$H$3*100 -> 100.45954 | Q13: =AVERAGE(B13,G13,L13) -> 0.001465795 | R13: =AVERAGE(C13,H13,M13) -> 0.0002639235 | T13: =AVERAGE(D13,I13,N13) -> 103.21933 | U13: =AVERAGE(E13,J13,O13) -> 99.644754 | W13: =_xlfn.STDEV.P(D13,I13,N13) -> 0.18253873 | X13: =_xlfn.STDEV.P(E13,J13,O13) -> 0.81478753
A14: 74.5085 | B14: 0.00166943 | C14: 0.000277877 | D14: =B14/$B$3*100 -> 103.63466 | E14: =C14/$C$3*100 -> 99.184046 | G14: 0.00127032 | H14: 0.000253179 | I14: =G14/$G$3*100 -> 103.39573 | J14: =H14/$H$3*100 -> 101.347 | Q14: =AVERAGE(B14,G14,L14) -> 0.001469875 | R14: =AVERAGE(C14,H14,M14) -> 0.000265528 | T14: =AVERAGE(D14,I14,N14) -> 103.5152 | U14: =AVERAGE(E14,J14,O14) -> 100.26552 | W14: =_xlfn.STDEV.P(D14,I14,N14) -> 0.11946217 | X14: =_xlfn.STDEV.P(E14,J14,O14) -> 1.0814779
... A109: 692.494 | B109: 0.00129108 | C109: 0.000244485 | D109: =B109/$B$3*100 -> 80.147497 | E109: =C109/$C$3*100 -> 87.265271 | G109: 0.00108197 | H109: 0.00026371 | I109: =G109/$G$3*100 -> 88.065278 | J109: =H109/$H$3*100 -> 105.56254 | Q109: =AVERAGE(B109,G109,L109) -> 0.001186525 | R109: =AVERAGE(C109,H109,M109) -> 0.0002540975 | T109: =AVERAGE(D109,I109,N109) -> 84.106387 | U109: =AVERAGE(E109,J109,O109) -> 96.413905 | W109: =_xlfn.STDEV.P(D109,I109,N109) -> 3.9588903 | X109: =_xlfn.STDEV.P(E109,J109,O109) -> 9.148634

Sheet 1480 P- 72 hpi
A1: Time | B1: Storage modulus | C1: Loss modulus | D1: Percent storage modulus | E1: Percent loss modulus | G1: Storage modulus | H1: Loss modulus | I1: Percent storage modulus | J1: Percent loss modulus | L1: Storage modulus | M1: Loss modulus | N1: Percent storage modulus | O1: Percent loss modulus | Q1: Average storage modulus | R1: Average loss modulus | T1: Average storage modulus/initial | U1: Average loss modulus/initial | W1: SD G' | X1: SD G''
A2: s | B2: MPa | C2: MPa | D2: MPa | E2: MPa | G2: MPa | H2: MPa | I2: MPa | J2: MPa | L2: MPa | M2: MPa | N2: MPa | O2: MPa | Q2: MPa | R2: MPa | T2: MPa | U2: MPa | W2: MPa | X2: MPa
A3: 6.09902 | B3: 0.00078509 | C3: 0.000173698 | D3: =B3/$B$3*100 -> 100 | E3: =C3/$C$3*100 -> 100 | G3: 0.000692412 | H3: 0.000154401 | I3: =G3/$G$3*100 -> 100 | J3: =H3/$H$3*100 -> 100 | L3: 0.000758243 | M3: 0.000161991 | N3: =L3/$L$3*100 -> 100 | O3: =M3/$M$3*100 -> 100 | Q3: =AVERAGE(B3,G3,L3) -> 0.00074524833 | R3: =AVERAGE(C3,H3,M3) -> 0.00016336333 | T3: =AVERAGE(D3,I3,N3) -> 100 | U3: =AVERAGE(E3,J3,O3) -> 100 | W3: =_xlfn.STDEV.P(D3,I3,N3) -> 0 | X3: =_xlfn.STDEV.P(E3,J3,O3) -> 0
A4: 12.4441 | B4: 0.00079105 | C4: 0.000175579 | D4: =B4/$B$3*100 -> 100.75915 | E4: =C4/$C$3*100 -> 101.08291 | G4: 0.000697681 | H4: 0.000155111 | I4: =G4/$G$3*100 -> 100.76096 | J4: =H4/$H$3*100 -> 100.45984 | L4: 0.000763628 | M4: 0.000165903 | N4: =L4/$L$3*100 -> 100.71019 | O4: =M4/$M$3*100 -> 102.41495 | Q4: =AVERAGE(B4,G4,L4) -> 0.00075078633 | R4: =AVERAGE(C4,H4,M4) -> 0.000165531 | T4: =AVERAGE(D4,I4,N4) -> 100.74344 | U4: =AVERAGE(E4,J4,O4) -> 101.31923 | W4: =_xlfn.STDEV.P(D4,I4,N4) -> 0.023516555 | X4: =_xlfn.STDEV.P(E4,J4,O4) -> 0.81547405
A5: 18.657 | B5: 0.000796746 | C5: 0.000174568 | D5: =B5/$B$3*100 -> 101.48467 | E5: =C5/$C$3*100 -> 100.50087 | G5: 0.00070299 | H5: 0.000154862 | I5: =G5/$G$3*100 -> 101.5277 | J5: =H5/$H$3*100 -> 100.29857 | L5: 0.000768993 | M5: 0.000164475 | N5: =L5/$L$3*100 -> 101.41775 | O5: =M5/$M$3*100 -> 101.53342 | Q5: =AVERAGE(B5,G5,L5) -> 0.000756243 | R5: =AVERAGE(C5,H5,M5) -> 0.000164635 | T5: =AVERAGE(D5,I5,N5) -> 101.47671 | U5: =AVERAGE(E5,J5,O5) -> 100.77762 | W5: =_xlfn.STDEV.P(D5,I5,N5) -> 0.045239366 | X5: =_xlfn.STDEV.P(E5,J5,O5) -> 0.54077358
A6: 24.8427 | B6: 0.000801902 | C6: 0.000173537 | D6: =B6/$B$3*100 -> 102.14141 | E6: =C6/$C$3*100 -> 99.90731 | G6: 0.000707014 | H6: 0.000155055 | I6: =G6/$G$3*100 -> 102.10886 | J6: =H6/$H$3*100 -> 100.42357 | L6: 0.000775077 | M6: 0.000167078 | N6: =L6/$L$3*100 -> 102.22013 | O6: =M6/$M$3*100 -> 103.1403 | Q6: =AVERAGE(B6,G6,L6) -> 0.000761331 | R6: =AVERAGE(C6,H6,M6) -> 0.00016522333 | T6: =AVERAGE(D6,I6,N6) -> 102.1568 | U6: =AVERAGE(E6,J6,O6) -> 101.15706 | W6: =_xlfn.STDEV.P(D6,I6,N6) -> 0.046712214 | X6: =_xlfn.STDEV.P(E6,J6,O6) -> 1.4181103
A7: 31.0469 | B7: 0.000805778 | C7: 0.000173617 | D7: =B7/$B$3*100 -> 102.63511 | E7: =C7/$C$3*100 -> 99.953367 | G7: 0.000711485 | H7: 0.000155401 | I7: =G7/$G$3*100 -> 102.75457 | J7: =H7/$H$3*100 -> 100.64766 | L7: 0.000776415 | M7: 0.000167173 | N7: =L7/$L$3*100 -> 102.39659 | O7: =M7/$M$3*100 -> 103.19894 | Q7: =AVERAGE(B7,G7,L7) -> 0.00076455933 | R7: =AVERAGE(C7,H7,M7) -> 0.000165397 | T7: =AVERAGE(D7,I7,N7) -> 102.59543 | U7: =AVERAGE(E7,J7,O7) -> 101.26666 | W7: =_xlfn.STDEV.P(D7,I7,N7) -> 0.14881477 | X7: =_xlfn.STDEV.P(E7,J7,O7) -> 1.3954225
A8: 37.1439 | B8: 0.000810466 | C8: 0.000175164 | D8: =B8/$B$3*100 -> 103.23224 | E8: =C8/$C$3*100 -> 100.84399 | G8: 0.000715974 | H8: 0.000157385 | I8: =G8/$G$3*100 -> 103.40289 | J8: =H8/$H$3*100 -> 101.93263 | L8: 0.000780241 | M8: 0.000169033 | N8: =L8/$L$3*100 -> 102.90118 | O8: =M8/$M$3*100 -> 104.34716 | Q8: =AVERAGE(B8,G8,L8) -> 0.00076889367 | R8: =AVERAGE(C8,H8,M8) -> 0.000167194 | T8: =AVERAGE(D8,I8,N8) -> 103.17877 | U8: =AVERAGE(E8,J8,O8) -> 102.37459 | W8: =_xlfn.STDEV.P(D8,I8,N8) -> 0.20828145 | X8: =_xlfn.STDEV.P(E8,J8,O8) -> 1.4639065
A9: 43.3649 | B9: 0.000814004 | C9: 0.00017582 | D9: =B9/$B$3*100 -> 103.68289 | E9: =C9/$C$3*100 -> 101.22166 | G9: 0.000718633 | H9: 0.000157959 | I9: =G9/$G$3*100 -> 103.78691 | J9: =H9/$H$3*100 -> 102.30439 | L9: 0.000784656 | M9: 0.000167587 | N9: =L9/$L$3*100 -> 103.48345 | O9: =M9/$M$3*100 -> 103.45451 | Q9: =AVERAGE(B9,G9,L9) -> 0.000772431 | R9: =AVERAGE(C9,H9,M9) -> 0.000167122 | T9: =AVERAGE(D9,I9,N9) -> 103.65108 | U9: =AVERAGE(E9,J9,O9) -> 102.32685 | W9: =_xlfn.STDEV.P(D9,I9,N9) -> 0.12591189 | X9: =_xlfn.STDEV.P(E9,J9,O9) -> 0.91169654
A10: 49.6091 | B10: 0.000819416 | C10: 0.000175087 | D10: =B10/$B$3*100 -> 104.37224 | E10: =C10/$C$3*100 -> 100.79966 | G10: 0.000724953 | H10: 0.000157404 | I10: =G10/$G$3*100 -> 104.69966 | J10: =H10/$H$3*100 -> 101.94494 | L10: 0.00078821 | M10: 0.000169303 | N10: =L10/$L$3*100 -> 103.95216 | O10: =M10/$M$3*100 -> 104.51383 | Q10: =AVERAGE(B10,G10,L10) -> 0.00077752633 | R10: =AVERAGE(C10,H10,M10) -> 0.00016726467 | T10: =AVERAGE(D10,I10,N10) -> 104.34135 | U10: =AVERAGE(E10,J10,O10) -> 102.41948 | W10: =_xlfn.STDEV.P(D10,I10,N10) -> 0.30594419 | X10: =_xlfn.STDEV.P(E10,J10,O10) -> 1.5529867
A11: 55.873 | B11: 0.000824224 | C11: 0.000175579 | D11: =B11/$B$3*100 -> 104.98465 | E11: =C11/$C$3*100 -> 101.08291 | G11: 0.0007264 | H11: 0.000157663 | I11: =G11/$G$3*100 -> 104.90864 | J11: =H11/$H$3*100 -> 102.11268 | L11: 0.000792408 | M11: 0.000169612 | N11: =L11/$L$3*100 -> 104.50581 | O11: =M11/$M$3*100 -> 104.70458 | Q11: =AVERAGE(B11,G11,L11) -> 0.00078101067 | R11: =AVERAGE(C11,H11,M11) -> 0.000167618 | T11: =AVERAGE(D11,I11,N11) -> 104.7997 | U11: =AVERAGE(E11,J11,O11) -> 102.63339 | W11: =_xlfn.STDEV.P(D11,I11,N11) -> 0.21011508 | X11: =_xlfn.STDEV.P(E11,J11,O11) -> 1.5236964
A12: 62.0034 | B12: 0.000826995 | C12: 0.000176041 | D12: =B12/$B$3*100 -> 105.3376 | E12: =C12/$C$3*100 -> 101.34889 | G12: 0.00073068 | H12: 0.000159328 | I12: =G12/$G$3*100 -> 105.52677 | J12: =H12/$H$3*100 -> 103.19104 | L12: 0.000796913 | M12: 0.000170313 | N12: =L12/$L$3*100 -> 105.09995 | O12: =M12/$M$3*100 -> 105.13732 | Q12: =AVERAGE(B12,G12,L12) -> 0.00078486267 | R12: =AVERAGE(C12,H12,M12) -> 0.00016856067 | T12: =AVERAGE(D12,I12,N12) -> 105.32144 | U12: =AVERAGE(E12,J12,O12) -> 103.22575 | W12: =_xlfn.STDEV.P(D12,I12,N12) -> 0.17462267 | X12: =_xlfn.STDEV.P(E12,J12,O12) -> 1.5468146
A13: 68.2662 | B13: 0.000830524 | C13: 0.000176225 | D13: =B13/$B$3*100 -> 105.78711 | E13: =C13/$C$3*100 -> 101.45482 | G13: 0.000734267 | H13: 0.000157985 | I13: =G13/$G$3*100 -> 106.04481 | J13: =H13/$H$3*100 -> 102.32123 | L13: 0.000797893 | M13: 0.000172203 | N13: =L13/$L$3*100 -> 105.22919 | O13: =M13/$M$3*100 -> 106.30405 | Q13: =AVERAGE(B13,G13,L13) -> 0.00078756133 | R13: =AVERAGE(C13,H13,M13) -> 0.00016880433 | T13: =AVERAGE(D13,I13,N13) -> 105.68704 | U13: =AVERAGE(E13,J13,O13) -> 103.36004 | W13: =_xlfn.STDEV.P(D13,I13,N13) -> 0.34040981 | X13: =_xlfn.STDEV.P(E13,J13,O13) -> 2.111571
A14: 74.3698 | B14: 0.000836181 | C14: 0.00017667 | D14: =B14/$B$3*100 -> 106.50766 | E14: =C14/$C$3*100 -> 101.71102 | G14: 0.000737141 | H14: 0.000159585 | I14: =G14/$G$3*100 -> 106.45988 | J14: =H14/$H$3*100 -> 103.35749 | L14: 0.000802384 | M14: 0.000170335 | N14: =L14/$L$3*100 -> 105.82148 | O14: =M14/$M$3*100 -> 105.1509 | Q14: =AVERAGE(B14,G14,L14) -> 0.000791902 | R14: =AVERAGE(C14,H14,M14) -> 0.00016886333 | T14: =AVERAGE(D14,I14,N14) -> 106.26301 | U14: =AVERAGE(E14,J14,O14) -> 103.40647 | W14: =_xlfn.STDEV.P(D14,I14,N14) -> 0.31281394 | X14: =_xlfn.STDEV.P(E14,J14,O14) -> 1.4047553
... A109: 692.516 | B109: 0.000796221 | C109: 0.000173482 | D109: =B109/$B$3*100 -> 101.4178 | E109: =C109/$C$3*100 -> 99.875646 | G109: 0.000716405 | H109: 0.000171487 | I109: =G109/$G$3*100 -> 103.46513 | J109: =H109/$H$3*100 -> 111.06599 | L109: 0.000765233 | M109: 0.00017502 | N109: =L109/$L$3*100 -> 100.92187 | O109: =M109/$M$3*100 -> 108.04304 | Q109: =AVERAGE(B109,G109,L109) -> 0.00075928633 | R109: =AVERAGE(C109,H109,M109) -> 0.00017332967 | T109: =AVERAGE(D109,I109,N109) -> 101.93493 | U109: =AVERAGE(E109,J109,O109) -> 106.32823 | W109: =_xlfn.STDEV.P(D109,I109,N109) -> 1.1007939 | X109: =_xlfn.STDEV.P(E109,J109,O109) -> 4.7266191

Sheet NAD003 P- 72 hpi
A1: Time | B1: Storage modulus | C1: Loss modulus | D1: Percent storage modulus | E1: Percent loss modulus | G1: Storage modulus | H1: Loss modulus | I1: Percent storage modulus | J1: Percent loss modulus | L1: Storage modulus | M1: Loss modulus | N1: Percent storage modulus | O1: Percent loss modulus | Q1: Average storage modulus | R1: Average loss modulus | T1: Average storage modulus/initial | U1: Average loss modulus/initial | W1: SD G' | X1: SD G''
A2: s | B2: MPa | C2: MPa | D2: MPa | E2: MPa | G2: MPa | H2: MPa | I2: MPa | J2: MPa | L2: MPa | M2: MPa | N2: MPa | O2: MPa | Q2: MPa | R2: MPa | T2: MPa | U2: MPa | W2: MPa | X2: MPa
A3: 6.27187 | B3: 0.000838671 | C3: 0.000178735 | D3: =B3/$B$3*100 -> 100 | E3: =C3/$C$3*100 -> 100 | G3: 0.000879384 | H3: 0.000175542 | I3: =G3/$G$3*100 -> 100 | J3: =H3/$H$3*100 -> 100 | L3: 0.00119672 | M3: 0.000218697 | N3: =L3/$L$3*100 -> 100 | O3: =M3/$M$3*100 -> 100 | Q3: =AVERAGE(B3,G3,L3) -> 0.00097159167 | R3: =AVERAGE(C3,H3,M3) -> 0.00019099133 | T3: =AVERAGE(D3,I3,N3) -> 100 | U3: =AVERAGE(E3,J3,O3) -> 100 | W3: =_xlfn.STDEV.P(D3,I3,N3) -> 0 | X3: =_xlfn.STDEV.P(E3,J3,O3) -> 0
A4: 12.4371 | B4: 0.000842771 | C4: 0.000180325 | D4: =B4/$B$3*100 -> 100.48887 | E4: =C4/$C$3*100 -> 100.88959 | G4: 0.000881577 | H4: 0.000175207 | I4: =G4/$G$3*100 -> 100.24938 | J4: =H4/$H$3*100 -> 99.809162 | L4: 0.00120296 | M4: 0.000218847 | N4: =L4/$L$3*100 -> 100.52143 | O4: =M4/$M$3*100 -> 100.06859 | Q4: =AVERAGE(B4,G4,L4) -> 0.00097576933 | R4: =AVERAGE(C4,H4,M4) -> 0.00019145967 | T4: =AVERAGE(D4,I4,N4) -> 100.41989 | U4: =AVERAGE(E4,J4,O4) -> 100.25578 | W4: =_xlfn.STDEV.P(D4,I4,N4) -> 0.12130049 | X4: =_xlfn.STDEV.P(E4,J4,O4) -> 0.46051312
A5: 18.5455 | B5: 0.000847008 | C5: 0.000183874 | D5: =B5/$B$3*100 -> 100.99407 | E5: =C5/$C$3*100 -> 102.87521 | G5: 0.000884167 | H5: 0.000175935 | I5: =G5/$G$3*100 -> 100.5439 | J5: =H5/$H$3*100 -> 100.22388 | L5: 0.00120718 | M5: 0.000221097 | N5: =L5/$L$3*100 -> 100.87406 | O5: =M5/$M$3*100 -> 101.09741 | Q5: =AVERAGE(B5,G5,L5) -> 0.00097945167 | R5: =AVERAGE(C5,H5,M5) -> 0.00019363533 | T5: =AVERAGE(D5,I5,N5) -> 100.80401 | U5: =AVERAGE(E5,J5,O5) -> 101.39883 | W5: =_xlfn.STDEV.P(D5,I5,N5) -> 0.19033801 | X5: =_xlfn.STDEV.P(E5,J5,O5) -> 1.1031854
A6: 24.7914 | B6: 0.000848042 | C6: 0.000181814 | D6: =B6/$B$3*100 -> 101.11736 | E6: =C6/$C$3*100 -> 101.72266 | G6: 0.000885527 | H6: 0.000173641 | I6: =G6/$G$3*100 -> 100.69856 | J6: =H6/$H$3*100 -> 98.917068 | L6: 0.00121108 | M6: 0.000218269 | N6: =L6/$L$3*100 -> 101.19995 | O6: =M6/$M$3*100 -> 99.804295 | Q6: =AVERAGE(B6,G6,L6) -> 0.00098154967 | R6: =AVERAGE(C6,H6,M6) -> 0.00019124133 | T6: =AVERAGE(D6,I6,N6) -> 101.00529 | U6: =AVERAGE(E6,J6,O6) -> 100.14801 | W6: =_xlfn.STDEV.P(D6,I6,N6) -> 0.21949682 | X6: =_xlfn.STDEV.P(E6,J6,O6) -> 1.1708809
A7: 31.107 | B7: 0.000851591 | C7: 0.000183635 | D7: =B7/$B$3*100 -> 101.54053 | E7: =C7/$C$3*100 -> 102.74149 | G7: 0.000886756 | H7: 0.000174988 | I7: =G7/$G$3*100 -> 100.83831 | J7: =H7/$H$3*100 -> 99.684406 | L7: 0.001215 | M7: 0.000219896 | N7: =L7/$L$3*100 -> 101.52751 | O7: =M7/$M$3*100 -> 100.54825 | Q7: =AVERAGE(B7,G7,L7) -> 0.000984449 | R7: =AVERAGE(C7,H7,M7) -> 0.00019283967 | T7: =AVERAGE(D7,I7,N7) -> 101.30212 | U7: =AVERAGE(E7,J7,O7) -> 100.99138 | W7: =_xlfn.STDEV.P(D7,I7,N7) -> 0.32800227 | X7: =_xlfn.STDEV.P(E7,J7,O7) -> 1.2867826
A8: 37.1924 | B8: 0.000853675 | C8: 0.000183875 | D8: =B8/$B$3*100 -> 101.78902 | E8: =C8/$C$3*100 -> 102.87577 | G8: 0.000887818 | H8: 0.000171674 | I8: =G8/$G$3*100 -> 100.95908 | J8: =H8/$H$3*100 -> 97.796539 | L8: 0.00121773 | M8: 0.000217627 | N8: =L8/$L$3*100 -> 101.75563 | O8: =M8/$M$3*100 -> 99.510739 | Q8: =AVERAGE(B8,G8,L8) -> 0.00098640767 | R8: =AVERAGE(C8,H8,M8) -> 0.00019105867 | T8: =AVERAGE(D8,I8,N8) -> 101.50124 | U8: =AVERAGE(E8,J8,O8) -> 100.06101 | W8: =_xlfn.STDEV.P(D8,I8,N8) -> 0.38361012 | X8: =_xlfn.STDEV.P(E8,J8,O8) -> 2.1097772
A9: 43.5262 | B9: 0.00085484 | C9: 0.000179254 | D9: =B9/$B$3*100 -> 101.92793 | E9: =C9/$C$3*100 -> 100.29037 | G9: 0.000890177 | H9: 0.000174161 | I9: =G9/$G$3*100 -> 101.22734 | J9: =H9/$H$3*100 -> 99.213294 | L9: 0.00122196 | M9: 0.000218604 | N9: =L9/$L$3*100 -> 102.1091 | O9: =M9/$M$3*100 -> 99.957475 | Q9: =AVERAGE(B9,G9,L9) -> 0.00098899233 | R9: =AVERAGE(C9,H9,M9) -> 0.000190673 | T9: =AVERAGE(D9,I9,N9) -> 101.75479 | U9: =AVERAGE(E9,J9,O9) -> 99.820381 | W9: =_xlfn.STDEV.P(D9,I9,N9) -> 0.38022777 | X9: =_xlfn.STDEV.P(E9,J9,O9) -> 0.45027522
A10: 49.6883 | B10: 0.00085338 | C10: 0.000177549 | D10: =B10/$B$3*100 -> 101.75385 | E10: =C10/$C$3*100 -> 99.336448 | G10: 0.000893126 | H10: 0.00017433 | I10: =G10/$G$3*100 -> 101.56268 | J10: =H10/$H$3*100 -> 99.309567 | L10: 0.00122604 | M10: 0.000217493 | N10: =L10/$L$3*100 -> 102.45003 | O10: =M10/$M$3*100 -> 99.449467 | Q10: =AVERAGE(B10,G10,L10) -> 0.00099084867 | R10: =AVERAGE(C10,H10,M10) -> 0.00018979067 | T10: =AVERAGE(D10,I10,N10) -> 101.92219 | U10: =AVERAGE(E10,J10,O10) -> 99.36516 | W10: =_xlfn.STDEV.P(D10,I10,N10) -> 0.38131298 | X10: =_xlfn.STDEV.P(E10,J10,O10) -> 0.060615133
A11: 55.8005 | B11: 0.000856499 | C11: 0.000178518 | D11: =B11/$B$3*100 -> 102.12574 | E11: =C11/$C$3*100 -> 99.878591 | G11: 0.000896116 | H11: 0.000180472 | I11: =G11/$G$3*100 -> 101.9027 | J11: =H11/$H$3*100 -> 102.80844 | L11: 0.0012295 | M11: 0.000217791 | N11: =L11/$L$3*100 -> 102.73915 | O11: =M11/$M$3*100 -> 99.585728 | Q11: =AVERAGE(B11,G11,L11) -> 0.00099403833 | R11: =AVERAGE(C11,H11,M11) -> 0.00019226033 | T11: =AVERAGE(D11,I11,N11) -> 102.25586 | U11: =AVERAGE(E11,J11,O11) -> 100.75759 | W11: =_xlfn.STDEV.P(D11,I11,N11) -> 0.35366088 | X11: =_xlfn.STDEV.P(E11,J11,O11) -> 1.455095
A12: 62.1114 | B12: 0.000859199 | C12: 0.000179895 | D12: =B12/$B$3*100 -> 102.44768 | E12: =C12/$C$3*100 -> 100.64901 | G12: 0.000898382 | H12: 0.00018356 | I12: =G12/$G$3*100 -> 102.16038 | J12: =H12/$H$3*100 -> 104.56757 | L12: 0.00123338 | M12: 0.000219191 | N12: =L12/$L$3*100 -> 103.06337 | O12: =M12/$M$3*100 -> 100.22588 | Q12: =AVERAGE(B12,G12,L12) -> 0.000996987 | R12: =AVERAGE(C12,H12,M12) -> 0.00019421533 | T12: =AVERAGE(D12,I12,N12) -> 102.55714 | U12: =AVERAGE(E12,J12,O12) -> 101.81415 | W12: =_xlfn.STDEV.P(D12,I12,N12) -> 0.37668504 | X12: =_xlfn.STDEV.P(E12,J12,O12) -> 1.9546068
A13: 68.3388 | B13: 0.000860296 | C13: 0.0001788 | D13: =B13/$B$3*100 -> 102.57848 | E13: =C13/$C$3*100 -> 100.03637 | G13: 0.000900562 | H13: 0.000184105 | I13: =G13/$G$3*100 -> 102.40828 | J13: =H13/$H$3*100 -> 104.87803 | L13: 0.00123712 | M13: 0.000219284 | N13: =L13/$L$3*100 -> 103.37589 | O13: =M13/$M$3*100 -> 100.26841 | Q13: =AVERAGE(B13,G13,L13) -> 0.000999326 | R13: =AVERAGE(C13,H13,M13) -> 0.000194063 | T13: =AVERAGE(D13,I13,N13) -> 102.78755 | U13: =AVERAGE(E13,J13,O13) -> 101.7276 | W13: =_xlfn.STDEV.P(D13,I13,N13) -> 0.42178411 | X13: =_xlfn.STDEV.P(E13,J13,O13) -> 2.2297049
